Workbook

Sheet TKB_LOP_SC
A1: Tiểu học và THCS UNIGO Năm học 2026 - 2027 Học kỳ 1 | F1: THỜI KHOÁ BIỂU số 1 | N1: THỜI KHOÁ BIỂU số 1 | X1: THỜI KHOÁ BIỂU số 1 | AJ1: THỜI KHOÁ BIỂU số 1
A4: THỨ | B4: TIẾT | C4: 1A1 | E4: 1C1 | G4: 2A1 | I4: 2C1 | K4: THỨ | L4: TIẾT | M4: 3A1 | O4: 3C1 | Q4: 4C1 | S4: 5C1 | U4: THỨ | V4: TIẾT | W4: 6A1 | Y4: 7A1 | AA4: 8A1 | AC4: TTH 1 | AE4: TTH2 | AG4: THỨ | AH4: TIẾT | AI4: TT3 | AK4: Blue Sky | AM4: Brighstar | AO4: Sunny | AQ4: Sunshine
C5: Sáng | D5: Chiều | E5: Sáng | F5: Chiều | G5: Sáng | H5: Chiều | I5: Sáng | J5: Chiều | M5: Sáng | N5: Chiều | O5: Sáng | P5: Chiều | Q5: Sáng | R5: Chiều | S5: Sáng | T5: Chiều | W5: Sáng | X5: Chiều | Y5: Sáng | Z5: Chiều | AA5: Sáng | AB5: Chiều | AC5: Sáng | AD5: Chiều | AE5: Sáng | AF5: Chiều | AI5: Sáng | AJ5: Chiều | AK5: Sáng | AL5: Chiều | AM5: Sáng | AN5: Chiều | AO5: Sáng | AP5: Chiều | AQ5: Sáng | AR5: Chiều
A6: 2 | B6: 1 | C6: Đạo đức - Ngọc Ánh | D6: GVVN - Trang | E6: Đạo đức - Nhi | F6: TViệt - Nhi | G6: Đạo đức - Linh TH | H6: Tiếng Trung - Thanh | I6: Đạo đức - Xuân | J6: GVNN - Tay, Trà | K6: 2 | L6: 1 | M6: HĐTN - Ngọc | N6: GDTC - Hồng | O6: Đạo đức - Ly | P6: TViệt - Ly | Q6: GVVN - Quỳnh | R6: Toán - Phương Anh | S6: HĐTN - Chi | T6: GVVN - Bích | U6: 2 | V6: 1 | W6: LS&ĐL - Hà | X6: GDĐP - Ánh NV | Y6: GDĐP - Ánh NV | Z6: Tin - Nguyên | AA6: Toán - Tân | AB6: Toán - Tân | AC6: SH tập thể - Hiền | AD6: HĐ tự chọn - Hiền | AE6: SH tập thể - MN1 | AF6: HĐ tự chọn - MN1 | AG6: 2 | AH6: 1 | AI6: SH tập thể - MN2 | AJ6: HĐ tự chọn - MN2 | AO6: GVNN - Aziz, Dung
B7: 2 | C7: GVVN - Trang | D7: TViệt - Ngọc Ánh | E7: GVNN - Tay, Huyền | F7: GVVN - Huyền | G7: TViệt - Linh TH | H7: Toán - Linh TH | I7: GVVN - Trà | J7: Science - Trà | L7: 2 | M7: Viết sáng tạo - Xuân | N7: GDTC - Hồng | O7: Toán - Chi | P7: Tiếng Trung - Thanh | Q7: TViệt - Ly | R7: TViệt - Ly | S7: Science - Bích | T7: GVNN - Tay, Bích | V7: 2 | W7: GVVN - Chánh | X7: Văn - Hà | Y7: Nhạc - Trang ÂN | Z7: Văn - Ánh NV | AA7: GVVN - Quỳnh | AB7: Tiếng Trung - Châu | AC7: Đọc sách - Hiền | AD7: TViệt - Hiền | AE7: Đọc sách - MN1 | AF7: GVVN - Trang | AH7: 2 | AI7: TViệt - MN2 | AJ7: GVVN - Trang | AK7: GVNN - Aziz Quỳnh | AO7: GVVN - Linh | AR7: GVNN - Aziz, Phượng
B8: 3 | C8: Toán - Ngọc Ánh | D8: TViệt - Ngọc Ánh | E8: Nhạc - Trang ÂN | F8: Toán - Phương Anh | G8: TViệt - Linh TH | H8: GVVN - Trang | I8: TViệt - Xuân | J8: Viết sáng tạo - Xuân | L8: 3 | M8: TViệt - Ngọc | N8: GVVN - Trà | O8: TViệt - Ly | P8: Science - Bích | Q8: HĐTN - Phương Anh | R8: Tiếng Trung - Thanh | S8: Toán - Chi | T8: Toán - Chi | V8: 3 | W8: GVNN - Tay, Chánh | X8: Văn - Hà | Y8: Toán - Tân | Z8: Tiếng Trung - Châu | AA8: LS&ĐL - Hà | AB8: GVNN - Tay, Quỳnh | AC8: GVVN - Huyền | AD8: GDTC - Hồng | AE8: GDTC - Hồng | AF8: TViệt - MN1 | AH8: 3 | AI8: Toán - MN2 | AJ8: Đọc sách - MN2 | AM8: GVNN - Aziz, Ngân | AN8: GVVN - Linh | AP8: GVNN - Aziz, Dung | AQ8: GVVN - Linh
B9: 4 | C9: Tin - Nguyên | D9: KCST - Ngọc Ánh | E9: Science - Trà | F9: TViệt - Nhi | G9: GVVN - Trang | H9: TNXH - Linh TH | I9: TViệt - Xuân | J9: Tiếng Trung - Thanh | L9: 4 | M9: TNXH - Nhi | N9: GVVN - Trà | O9: Toán - Chi | P9: GVNN - Tay, Bích | Q9: GVNN - Tay, Quỳnh | R9: Đạo đức - Ly | S9: TViệt - Ngọc | T9: TViệt - Ngọc | V9: 4 | W9: Nhạc - Trang ÂN | X9: Tiếng Trung - Châu | Y9: GVVN - Chánh | Z9: LS&ĐL - Hà | AA9: Văn - Ánh NV | AB9: HĐTN - Phương Anh | AC9: GVNN - Aziz, Huyền | AD9: GDTC - Hồng | AE9: GDTC - Hồng | AF9: GVNN - Aziz, Huyền | AH9: 4 | AI9: Toán - MN2 | AJ9: GVNN - Kel, Huyền | AL9: GVVN - Linh
B10: 5 | L10: 5 | V10: 5 | W10: Toán - Tân | Y10: GVVN - Chánh | AA10: Văn - Ánh NV | AH10: 5
A11: 3 | B11: 1 | C11: TViệt - Ngọc Ánh | D11: TNXH - Ngọc Ánh | E11: Toán - Phương Anh | F11: GVVN - Huyền | G11: TViệt - LinhTH | H11: Tin - Nguyên | I11: Toán - Chi | J11: TNXH - Xuân | K11: 3 | L11: 1 | M11: TDNN - Nhi | N11: GVVN - Trà | O11: GDTC - Hồng | P11: Toán - Chi | Q11: Nhạc - Trang ÂN | R11: GVVN - Quỳnh | S11: GVNN - Tay, Bích | T11: TViệt - Ngọc | U11: 3 | V11: 1 | W11: KHTN - Nhung | X11: Toán - Tân | Y11: GVNN - Tay, Chánh | Z11: GVNN - Tay, Chánh | AA11: Toán - Tân | AB11: KHTN - Nhung | AC11: Toán - Hiền | AD11: HĐ tự chọn - Hiền | AE11: Toán - MN1 | AF11: HĐ tự chọn - MN1 | AG11: 3 | AH11: 1 | AI11: Tìm hiểu thiên nhiên - MN2 | AJ11: HĐ tự chọn - MN2 | AQ11: GVNN - Aziz, Phượng
B12: 2 | C12: TViệt - Ngọc Ánh | D12: Toán - Ngọc Ánh | E12: GVNN - Tay, Huyền | F12: Tin - Nguyên | G12: TViệt - Linh TH | H12: GVVN - Trang | I12: TViệt - Xuân | J12: GVVN - Trà | L12: 2 | M12: Nhạc - Trang ÂN | N12: Toán - Ngọc | O12: GDTC - Hồng | P12: TViệt - Ly | Q12: GVNN - Tay, Quỳnh | R12: Toán - Phương Anh | S12: LS&ĐL - Ly | T12: GVVN - Bích | V12: 2 | W12: KHTN - Nhung | X12: Văn - Hà | Y12: Toán - Tân | Z12: Toán - Tân | AA12: GDCD - Hà | AB12: KHTN - Nhung | AC12: Toán - Hiền | AD12: Tìm hiểu thiên nhiên - Hiền | AE12: Toán - MN1 | AF12: Tìm hiểu thiên nhiên - MN1 | AH12: 2 | AI12: Lối sống - MN2 | AJ12: Tìm hiểu thiên nhiên - MN2 | AK12: GVNN - Aziz, Quỳnh | AN12: GVVN - Linh | AP12: GVNN - Aziz, Dung
B13: 3 | C13: Nhạc - Trang ÂN | D13: KCST - Ngọc Ánh | E13: TViệt - Nhi | F13: GDTC - Hồng | G13: GVVN - Trang | H13: Toán - Linh TH | I13: Science - Trà | J13: Toán - Chi | L13: 3 | M13: TViệt - Ngọc | N13: Toán - Ngọc | O13: GVNN - Tay, Bích | P13: TViệt - Ly | Q13: LS&ĐL - Ly | R13: Science - Quỳnh | S13: Tin - Nguyên | T13: Science - Bích | V13: 3 | W13: Văn - Hà | X13: Đọc sách - Hà | Y13: KHTN - Nhung | Z13: Tin - Nguyên | AA13: GVNN - Tay, Quỳnh | AB13: Văn - Ánh NV | AC13: Tìm hiểu thiên nhiên - Hiền | AD13: TViệt - Hiền | AE13: Tìm hiểu thiên nhiên - MN1 | AF13: GVVN - Trang | AH13: 3 | AI13: GDTC - Hồng | AJ13: GVVN - Trang | AL13: GVNN - Aziz, Quỳnh | AM13: GVNN - Aziz, Ngân | AO13: GVVN - Linh
B14: 4 | C14: GVVN - Trang | D14: GVVN - Trang | E14: TViệt - Nhi | F14: GDTC - Hồng | G14: TNXH - Linh TH | H14: Toán - Linh TH | I14: GVNN - Tay, Trà | J14: TViệt - Xuân | L14: 4 | M14: TViệt - Ngọc | N14: GVVN - Trà | O14: Toán - Chi | P14: GVVN - Bích | Q14: Toán - Phương Anh | R14: TViệt - Ly | S14: Robotics - Nguyên | T14: Toán - Chi | V14: 4 | W14: GVNN - Tay, Chánh | X14: Toán - Tân | Y14: KHTN - Nhung | Z14: Robotics - Nguyên | AA14: GVVN - Quỳnh | AB14: Văn - Ánh NV | AC14: Lối sống - Hiền | AD14: GVVN - Huyền | AE14: Lối sống - MN1 | AF14: TViệt - MN1 | AH14: 4 | AI14: GDTC - Hồng | AJ14: TViệt - MN2 | AN14: GVNN - Aziz, Ngân | AR14: GVVN - Linh
B15: 5 | L15: 5 | V15: 5 | W15: GVNN - Tay, Chánh | Y15: Văn - Ánh NV | AA15: Toán - Tân | AH15: 5
A16: 4 | B16: 1 | C16: TViệt - Ngọc Ánh | D16: TNXH - Ngọc Ánh | E16: GVVN - Huyền | F16: Science - Trà | G16: GVNN - Aziz, Trang | H16: GVNN - Aziz, Trang | I16: GVNN - Tay, Trà | J16: Toán - Chi | K16: 4 | L16: 1 | M16: Toán - Ngọc | N16: Tiếng Trung - Thanh | O16: Toán - Chi | P16: Mĩ thuật - Phương | Q16: TViệt - Ly | R16: Toán - Phương Anh | S16: GVVN - Bích | T16: GVNN - Tay, Bích | U16: 4 | V16: 1 | W16: Tiếng Trung - Châu | X16: GVNN - Tay, Chánh | Y16: Văn - Ánh NV | Z16: Toán - Tân | AA16: Toán - Tân | AB16: Văn - Ánh NV | AC16: Lối sống - Hiền | AD16: HĐ tự chọn - Hiền | AE16: Lối sống - MN1 | AF16: HĐ tự chọn - MN1 | AG16: 4 | AH16: 1 | AI16: Mĩ thuật - Phương | AJ16: HĐ tự chọn - MN2 | AO16: GVVN - Linh
B17: 2 | C17: TViệt - Ngọc Ánh | D17: GVNN - Aziz, Trang | E17: TViệt - Nhi | F17: Tiếng Trung - Thanh | G17: Viết sáng tạo - Xuân | H17: TViệt - Linh TH | I17: Toán - Chi | J17: GVVN - Trà | L17: 2 | M17: Robotics - Nguyên | N17: TNXH - Nhi | O17: GVNN - Tay, Bích | P17: TViệt - Ly | Q17: GVVN - Quỳnh | R17: Science - Quỳnh | S17: TViệt - Ly | T17: Toán - Chi | V17: 2 | W17: GVVN - Chánh | X17: GVVN - Chánh | Y17: Tiếng Trung - Châu | Z17: LS&ĐL - Hà | AA17: Nhạc - Trang ÂN | AB17: Mĩ thuật - Phương | AC17: KCST - Hiền | AD17: GVVN - Huyền | AE17: GVNN - Aziz, Huyền | AF17: Toán - MN1 | AH17: 2 | AI17: GVNN - Aziz, Huyền | AJ17: Toán - MN2 | AK17: GVVN - Linh | AP17: GVVN - Linh
B18: 3 | C18: Toán - Ngọc Ánh | D18: Tiếng Trung - Thanh | E18: TViệt - Nhi | F18: GVNN - Tay, Huyền | G18: GDTC - Hồng | H18: TViệt - Linh TH | I18: TViệt - Xuân | J18: GDTC - Hồng | L18: 3 | M18: GVNN - Aziz, Trà | N18: GVNN - Aziz, Trà | O18: Science - Bích | P18: GVVN - Bích | Q18: Mĩ thuật - Phương | R18: Tin - Nguyên | S18: Nhạc - Trang ÂN | T18: Mĩ thuật - Phương | V18: 3 | W18: Văn - Hà | X18: GDCD - Hà | Y18: GVVN - Chánh | Z18: GVNN - Tay, Chánh | AA18: Tiếng Trung - Châu | AB18: GVVN - Quỳnh | AC18: GVVN - Huyền | AD18: Toán - Hiền | AE18: GVVN - Trang | AF18: GVVN - Trang | AH18: 3 | AI18: GVVN - Trang | AJ18: GVVN - Trang | AL18: GVVN - Linh | AM18: GVVN - Linh
B19: 4 | C19: GVNN - Aziz, Trang | D19: Mĩ thuật - Phương | E19: KCST - Nhi | F19: Toán - Phương Anh | G19: GDTC - Hồng | H19: Robotics - Nguyên | I19: TViệt - Xuân | J19: GDTC - Hồng | L19: 4 | M19: TViệt - Ngọc | N19: Toán - Ngọc | O19: Tin - Nguyên | P19: TNXH - Nhi | Q19: Toán - Phương Anh | R19: GVNN - Tay, Quỳnh | S19: Toán - Chi | T19: Tiếng Trung - Thanh | V19: 4 | W19: Văn - Hà | X19: Toán - Tân | Y19: Văn - Ánh NV | Z19: Đọc sách - Ánh NV | AA19: GVNN - Tay, Quỳnh | AB19: LS&ĐL - Hà | AC19: Cảm xúc xã hội - Hiền | AD19: VĐ Ngoài trời - Hiền | AE19: Mĩ thuật - Phương | AF19: VĐ Ngoài trời - MN1 | AH19: 4 | AI19: Lối sống - MN2 | AJ19: VĐ Ngoài trời - MN2 | AN19: GVVN - Linh | AQ19: GVVN - Linh | AR19: GVNN - Aziz, Phượng
B20: 5 | L20: 5 | V20: 5 | W20: Mĩ thuật - Phương | Y20: GVNN - Tay, Chánh | AA20: Đọc sách - Ánh NV | AH20: 5
A21: 5 | B21: 1 | C21: GVNN - Aziz, Trang | D21: GVNN - Aziz, Trang | E21: GVVN - Huyền | F21: TViệt - Nhi | G21: Nhạc - Trang ÂN | H21: Viết sáng tạo - Xuân | I21: GVVN - Trà | J21: Toán - Chi | K21: 5 | L21: 1 | M21: Toán - Ngọc | N21: Tin - Nguyên | O21: GVNN - Tay, Bích | P21: TViệt - Ly | Q21: Toán - Phương Anh | R21: Toán - Phương Anh | S21: GDTC - Hồng | T21: GVNN - Tay, Bích | U21: 5 | V21: 1 | W21: KHTN - Nhung | X21: Toán - Tân | Y21: GVNN - Tay, Chánh | Z21: GVVN - Chánh | AA21: GVVN - Quỳnh | AB21: KHTN - Nhung | AC21: TViệt - Hiền | AD21: HĐ tự chọn - Hiền | AE21: TViệt - MN1 | AF21: HĐ tự chọn - MN1 | AG21: 5 | AH21: 1 | AI21: Tin - Nguyên | AJ21: HĐ tự chọn - MN2 | AO21: GVVN - Linh
B22: 2 | C22: Robotics - Nguyên | D22: TViệt - Ngọc Ánh | E22: GVNN - Tay, Huyền | F22: TViệt - Nhi | G22: GVNN - Aziz, Trang | H22: Toán - Linh TH | I22: Toán - Chi | J22: GVVN - Trà | L22: 2 | M22: TViệt - Ngọc | N22: Toán - Ngọc | O22: Nhạc - Trang ÂN | P22: GVVN - Bích | Q22: Science - Quỳnh | R22: GVNN - Tay, Quỳnh | S22: GDTC - Hồng | T22: Đạo đức - Xuân | V22: 2 | W22: KHTN - Nhung | X22: GVVN - Chánh | Y22: Toán - Tân | Z22: Toán - Tân | AA22: LS&ĐL - Hà | AB22: KHTN - Nhung | AC22: Vận động theo nhạc - Hiền | AD22: Tin - Nguyên | AE22: Cảm xúc xã hội - MN1 | AF22: GVVN - Trang | AH22: 2 | AI22: TViệt - MN2 | AJ22: GVVN - Trang | AM22: GVVN - Linh | AN22: GVVN - Linh | AP22: GVNN - Aziz, Dung
B23: 3 | C23: GDTC - Hồng | D23: TViệt - Ngọc Ánh | E23: Toán - Phương Anh | F23: Toán - Phương Anh | G23: TDNN - Linh TH | H23: TViệt - Linh TH | I23: Nhạc - Trang ÂN | J23: TNXH - Xuân | L23: 3 | M23: GVNN - Aziz, Trà | N23: GVNN - Aziz, Trà | O23: Toán - Chi | P23: Toán - Chi | Q23: TViệt - Ly | R23: GDTC - Hồng | S23: GVVN - Bích | T23: TViệt - Ngọc | V23: 3 | W23: GVNN - Tay, Chánh | X23: GVNN - Tay, Chánh | Y23: KHTN - Nhung | Z23: Văn - Ánh NV | AA23: Văn - Ánh NV | AB23: GVVN - Quỳnh | AC23: TViệt - Hiền | AD23: GVVN - Huyền | AE23: GVVN - Trang | AF23: Tin - Nguyên | AH23: 3 | AI23: GVVN - Trang | AJ23: Vận động theo nhạc - MN2 | AK23: GVVN - Linh | AL23: GVVN - Linh
B24: 4 | C24: GDTC - Hồng | D24: Toán - Ngọc Ánh | E24: TNXH - Nhi | F24: Robotics - Nguyên | G24: GVNN - Aziz, Trang | H24: TViệt - Linh TH | I24: Robotics - Nguyên | J24: GVNN - Tay, Trà | L24: 4 | M24: Viết sáng tạo - Xuân | N24: Đọc sách - Xuân | O24: GVVN - Bích | P24: Science - Bích | Q24: GVVN - Quỳnh | R24: GDTC - Hồng | S24: Toán - Chi | T24: Toán - Chi | V24: 4 | W24: LS&ĐL - Hà | X24: HĐTN - Phương Anh | Y24: KHTN - Nhung | Z24: Văn - Ánh NV | AA24: Văn - Ánh NV | AB24: Toán - Tân | AC24: GVVN - Huyền | AD24: GVNN - Aziz, Huyền | AE24: KCST - MN1 | AF24: Vận động theo nhạc - MN1 | AH24: 4 | AI24: Cảm xúc xã hội - MN2 | AJ24: Cãm xúc xã hội - MN2 | AR24: GVVN - Linh
B25: 5 | L25: 5 | V25: 5 | W25: Toán - Tân | Y25: GVNN - Tay, Chánh | AA25: GDĐP - Ánh NV | AH25: 5
A26: 6 | B26: 1 | C26: TViệt - Ngọc Ánh | D26: GVVN - Trang | E26: TViệt - Nhi | F26: GVVN - Huyền | G26: TDNN - Linh TH | H26: Đọc sách - Xuân | I26: Tin - Nguyên | J26: GVVN - Trà | K26: 6 | L26: 1 | M26: TViệt - Ngọc | N26: Đạo đức - Nhi | O26: Toán - Chi | P26: Toán - Chi | Q26: Toán - Phương Anh | R26: TViệt - Ly | S26: GVVN - Bích | T26: Science - Bích | U26: 6 | V26: 1 | W26: LS&ĐL - Hà | X26: GDTC - Hồng | Y26: Mĩ thuật - Phương | Z26: Toán - Tân | AA26: GDTC - Hồng | AB26: Tin - Nguyên | AC26: GVNN - Aziz Huyền | AD26: HĐ tự chọn - Hiền | AE26: Nhạc - Trang ÂN | AF26: HĐ tự chọn - MN1 | AG26: 6 | AH26: 1 | AI26: TViệt - MN2 | AJ26: HĐ tự chọn - MN2 | AQ26: GVVN - Linh
B27: 2 | C27: TViệt -Ngọc Ánh | D27: Đọc sách - Xuân | E27: GVVN - Huyền | F27: KCST - Nhi | G27: GVVN - Trang | H27: GVVN - Trang | I27: Mĩ thuật - Phương | J27: Toán - Chi | L27: 2 | M27: TViệt - Ngọc | N27: TViệt - Ngọc | O27: Robotics - Nguyên | P27: TViệt - Ly | Q27: GVVN - Quỳnh | R27: Toán - Phương Anh | S27: Toán - Chi | T27: GVVN - Bích | V27: 2 | W27: Toán - Tân | X27: GDTC - Hồng | Y27: GDCD - Hà | Z27: Toán - Tân | AA27: GDTC - Hồng | AB27: Robotics - Nguyên | AC27: Cãm xúc xã hội - Hiền | AD27: Mĩ thuật - Phương | AE27: TViệt - MN1 | AF27: Cảm xúc xã hội - MN1 | AH27: 2 | AI27: Nhạc - Trang ÂN | AJ27: KCST - MN2 | AK27: GVNN - Aziz, Quỳnh | AN27: GVVN - Linh | AO27: GVVN - Linh | AR27: GVNN - Aziz, Phượng
B28: 3 | C28: GVVN - Trang | D28: TViệt - Ngọc Ánh | E28: Mĩ thuật - Phương | F28: TNXH - Nhi | G28: Toán - Linh TH | H28: Mĩ thuật - Phương | I28: TViệt - Xuân | J28: Viết sáng tạo - Xuân | L28: 3 | M28: GVVN - Trà | N28: GVVN - Trà | O28: TNXH - Nhi | P28: GVVN - Bích | Q28: TViệt - Ly | R28: Robotics - Nguyên | S28: TViệt - Ngọc | T28: LS&ĐL - Ly | V28: 3 | W28: Toán - Tân | X28: Văn - Hà | Y28: LS&ĐL - Hà | Z28: Văn - Ánh NV | AA28: GVNN - Tay, Quỳnh | AB28: Toán - Tân | AC28: Nhạc - Trang ÂN | AD28: GVNN - Aziz, Huyền | AE28: TViệt - MN1 | AF28: Toán - MN1 | AH28: 3 | AI28: TViệt - MN2 | AJ28: Toán - MN2 | AL28: GVVN - Linh | AM28: GVNN - Aziz, Ngân
B29: 4 | C29: Toán - Ngọc Ánh | D29: HĐTN - Ngọc Ánh | E29: Toán - Phương Anh | F29: HĐTN - Nhi | G29: Toán - Linh TH | H29: HĐTN - Linh TH | I29: TViệt - Xuân | J29: HĐTN - Xuân | L29: 4 | M29: Mĩ thuật - Phương | N29: Toán - Ngọc | O29: GVVN - Bích | P29: HĐTN - Ly | Q29: LS&ĐL - Ly | R29: GVVN - Quỳnh | S29: TViệt - Ngọc | T29: Toán - Chi | V29: 4 | W29: Tin - Nguyên | X29: Văn - Hà | Y29: GDTC - Hồng | Z29: Văn - Ánh NV | AA29: GVVN - Quỳnh | AB29: Toán - Tân | AC29: TViệt - Hiền | AD29: Toán - Hiền | AE29: GVNN - Aziz, Huyền | AF29: GVNN - Aziz, Huyền | AH29: 4 | AI29: GVNN - Aziz, Huyền | AJ29: GVNN - Aziz, Huyền | AR29: GVVN - Linh
B30: 5 | L30: 5 | V30: 5 | W30: Robotics - Nguyên | Y30: GDTC - Hồng | AA30: Văn - Ánh NV | AH30: 5
D32: PHT THƯỜNG TRỰC | I32: NGƯỜI LẬP | N32: PHT THƯỜNG TRỰC | S32: NGƯỜI LẬP | W32: PHT THƯỜNG TRỰC | AB32: NGƯỜI LẬP | AI32: PHT THƯỜNG TRỰC | AN32: NGƯỜI LẬP
D35: Nguyễn Văn Khoa | I35: Trịnh Kiều Trang | N35: Nguyễn Văn Khoa | S35: Trịnh Kiều Trang | W35: Nguyễn Văn Khoa | AB35: Trịnh Kiều Trang | AI35: Nguyễn Văn Khoa | AN35: Trịnh Kiều Trang

Sheet TKB_GV_SC
A1: Tiểu học và THCS UNIGO Năm học 2024 - 2025 Học kỳ 1 | D1: THỜI KHOÁ BIỂU số 1
A4: THỨ | B4: TIẾT | C4: Chánh | E4: Châu | G4: quỳnh | I4: Chi | K4: Chi | M4: Trang | O4: Hiền | Q4: Hồng | S4: Quỳnh | U4: Ánh NV | W4: Linh | Y4: Ngọc | AA4: Trang | AC4: Nam | AE4: Bích | AG4: Trang | AI4: Nhung | AK4: Phương | AM4: Ly | AO4: Xuân | AQ4: Chánh | AS4: Chi | AU4: GVM | AW4: GVM | AY4: GVM | BA4: GVM | BC4: GVM | BE4: GVM | BG4: GVM | BI4: GVM | BK4: GVM | BM4: GVM | BO4: Kel | BQ4: Tay | BS4: Wady | BU4: Moe
C5: Sáng | D5: Chiều | E5: Sáng | F5: Chiều | G5: Sáng | H5: Chiều | I5: Sáng | J5: Chiều | K5: Sáng | L5: Chiều | M5: Sáng | N5: Chiều | O5: Sáng | P5: Chiều | Q5: Sáng | R5: Chiều | S5: Sáng | T5: Chiều | U5: Sáng | V5: Chiều | W5: Sáng | X5: Chiều | Y5: Sáng | Z5: Chiều | AA5: Sáng | AB5: Chiều | AC5: Sáng | AD5: Chiều | AE5: Sáng | AF5: Chiều | AG5: Sáng | AH5: Chiều | AI5: Sáng | AJ5: Chiều | AK5: Sáng | AL5: Chiều | AM5: Sáng | AN5: Chiều | AO5: Sáng | AP5: Chiều | AQ5: Sáng | AR5: Chiều | AS5: Sáng | AT5: Chiều | AU5: Sáng | AV5: Chiều | AW5: Sáng | AX5: Chiều | AY5: Sáng | AZ5: Chiều | BA5: Sáng | BB5: Chiều | BC5: Sáng | BD5: Chiều | BE5: Sáng | BF5: Chiều | BG5: Sáng | BH5: Chiều | BI5: Sáng | BJ5: Chiều | BK5: Sáng | BL5: Chiều | BM5: Sáng | BN5: Chiều | BO5: Sáng | BP5: Chiều | BQ5: Sáng | BR5: Chiều | BS5: Sáng | BT5: Chiều | BU5: Sáng | BV5: Chiều
A6: 2 | B6: 1 | C6: =IFERROR(VLOOKUP($A$6&$C$5&$B6&$C$4,TKB_LOP_CHECK!$B$65:$J$860,9,0),"") | D6: =IFERROR(VLOOKUP($A$6&$D$5&$B6&$C$4,TKB_LOP_CHECK!$B$65:$J$860,9,0),"") | E6: =IFERROR(VLOOKUP($A$6&$C$5&$B6&$E$4,TKB_LOP_CHECK!$B$65:$J$860,9,0),"") | F6: =IFERROR(VLOOKUP($A$6&$D$5&$B6&$E$4,TKB_LOP_CHECK!$B$65:$J$860,9,0),"") | G6: =IFERROR(VLOOKUP($A$6&$C$5&$B6&$G$4,TKB_LOP_CHECK!$B$65:$J$860,9,0),"") -> GVVN -4C1 | H6: =IFERROR(VLOOKUP($A$6&$D$5&$B6&$G$4,TKB_LOP_CHECK!$B$65:$J$860,9,0),"") | I6: =IFERROR(VLOOKUP($A$6&$C$5&$B6&$I$4,TKB_LOP_CHECK!$B$65:$J$860,9,0),"") -> HĐTN -5C1 | J6: =IFERROR(VLOOKUP($A$6&$D$5&$B6&$I$4,TKB_LOP_CHECK!$B$65:$J$860,9,0),"") | K6: =IFERROR(VLOOKUP($A$6&$C$5&$B6&$K$4,TKB_LOP_CHECK!$B$65:$J$860,9,0),"") -> HĐTN -5C1 | L6: =IFERROR(VLOOKUP($A$6&$D$5&$B6&$K$4,TKB_LOP_CHECK!$B$65:$J$860,9,0),"") | M6: =IFERROR(VLOOKUP($A$6&$C$5&$B6&$M$4,TKB_LOP_CHECK!$B$65:$J$860,9,0),"") | N6: =IFERROR(VLOOKUP($A$6&$D$5&$B6&$M$4,TKB_LOP_CHECK!$B$65:$J$860,9,0),"") -> GVVN -1A1 | O6: =IFERROR(VLOOKUP($A$6&$C$5&$B6&$O$4,TKB_LOP_CHECK!$B$65:$J$860,9,0),"") -> SH tập thể -TTH1 | P6: =IFERROR(VLOOKUP($A$6&$D$5&$B6&$O$4,TKB_LOP_CHECK!$B$65:$J$860,9,0),"") -> HĐ tự chọn -TTH1 | Q6: =IFERROR(VLOOKUP($A$6&$C$5&$B6&$Q$4,TKB_LOP_CHECK!$B$65:$J$860,9,0),"") | R6: =IFERROR(VLOOKUP($A$6&$D$5&$B6&$Q$4,TKB_LOP_CHECK!$B$65:$J$860,9,0),"") -> GDTC -3A1 | S6: =IFERROR(VLOOKUP($A$6&$C$5&$B6&$S$4,TKB_LOP_CHECK!$B$65:$J$860,9,0),"") -> GVVN -4C1 | T6: =IFERROR(VLOOKUP($A$6&$D$5&$B6&$S$4,TKB_LOP_CHECK!$B$65:$J$860,9,0),"") | U6: =IFERROR(VLOOKUP($A$6&$C$5&$B6&$U$4,TKB_LOP_CHECK!$B$65:$J$860,9,0),"") -> GDĐP -7A1 | V6: =IFERROR(VLOOKUP($A$6&$D$5&$B6&$U$4,TKB_LOP_CHECK!$B$65:$J$860,9,0),"") -> GDĐP -6A1 | W6: =IFERROR(VLOOKUP($A$6&$C$5&$B6&$W$4,TKB_LOP_CHECK!$B$65:$J$860,9,0),"") | X6: =IFERROR(VLOOKUP($A$6&$D$5&$B6&$W$4,TKB_LOP_CHECK!$B$65:$J$860,9,0),"") | Y6: =IFERROR(VLOOKUP($A$6&$C$5&$B6&$Y$4,TKB_LOP_CHECK!$B$65:$J$860,9,0),"") | Z6: =IFERROR(VLOOKUP($A$6&$D$5&$B6&$Y$4,TKB_LOP_CHECK!$B$65:$J$860,9,0),"") | AA6: =IFERROR(VLOOKUP($A$6&$C$5&$B6&$AA$4,TKB_LOP_CHECK!$B$65:$J$860,9,0),"") | AB6: =IFERROR(VLOOKUP($A$6&$D$5&$B6&$AA$4,TKB_LOP_CHECK!$B$65:$J$860,9,0),"") -> GVVN -1A1 | AC6: =IFERROR(VLOOKUP($A$6&$C$5&$B6&$AC$4,TKB_LOP_CHECK!$B$65:$J$860,9,0),"") | AD6: =IFERROR(VLOOKUP($A$6&$D$5&$B6&$AC$4,TKB_LOP_CHECK!$B$65:$J$860,9,0),"") | AE6: =IFERROR(VLOOKUP($A$6&$C$5&$B6&$AE$4,TKB_LOP_CHECK!$B$65:$J$860,9,0),"") | AF6: =IFERROR(VLOOKUP($A$6&$D$5&$B6&$AE$4,TKB_LOP_CHECK!$B$65:$J$860,9,0),"") -> GVVN -5C1 | AG6: =IFERROR(VLOOKUP($A$6&$C$5&$B6&$AG$4,TKB_LOP_CHECK!$B$65:$J$860,9,0),"") | AH6: =IFERROR(VLOOKUP($A$6&$D$5&$B6&$AG$4,TKB_LOP_CHECK!$B$65:$J$860,9,0),"") -> GVVN -1A1 | AI6: =IFERROR(VLOOKUP($A$6&$C$5&$B6&$AI$4,TKB_LOP_CHECK!$B$65:$J$860,9,0),"") | AJ6: =IFERROR(VLOOKUP($A$6&$D$5&$B6&$AI$4,TKB_LOP_CHECK!$B$65:$J$860,9,0),"") | AK6: =IFERROR(VLOOKUP($A$6&$C$5&$B6&$AK$4,TKB_LOP_CHECK!$B$65:$J$860,9,0),"") | AL6: =IFERROR(VLOOKUP($A$6&$D$5&$B6&$AK$4,TKB_LOP_CHECK!$B$65:$J$860,9,0),"") | AM6: =IFERROR(VLOOKUP($A$6&$C$5&$B6&$AM$4,TKB_LOP_CHECK!$B$65:$J$860,9,0),"") -> Đạo đức -3C1 | AN6: =IFERROR(VLOOKUP($A$6&$D$5&$B6&$AM$4,TKB_LOP_CHECK!$B$65:$J$860,9,0),"") -> TViệt -3C1 | AO6: =IFERROR(VLOOKUP($A$6&$C$5&$B6&$AO$4,TKB_LOP_CHECK!$B$65:$J$860,9,0),"") -> Đạo đức -2C1 | AP6: =IFERROR(VLOOKUP($A$6&$D$5&$B6&$AO$4,TKB_LOP_CHECK!$B$65:$J$860,9,0),"") | AQ6: =IFERROR(VLOOKUP($A$6&$C$5&$B6&$AQ$4,TKB_LOP_CHECK!$B$65:$J$860,9,0),"") | AR6: =IFERROR(VLOOKUP($A$6&$D$5&$B6&$AQ$4,TKB_LOP_CHECK!$B$65:$J$860,9,0),"") | AS6: =IFERROR(VLOOKUP($A$6&$C$5&$B6&$AS$4,TKB_LOP_CHECK!$B$65:$J$860,9,0),"") -> HĐTN -5C1 | AT6: =IFERROR(VLOOKUP($A$6&$D$5&$B6&$AS$4,TKB_LOP_CHECK!$B$65:$J$860,9,0),"") | AU6: =IFERROR(VLOOKUP($A$6&$C$5&$B6&$AU$4,TKB_LOP_CHECK!$B$65:$J$860,9,0),"") | AV6: =IFERROR(VLOOKUP($A$6&$D$5&$B6&$AU$4,TKB_LOP_CHECK!$B$65:$J$860,9,0),"") | AW6: =IFERROR(VLOOKUP($A$6&$C$5&$B6&$AW$4,TKB_LOP_CHECK!$B$65:$J$860,9,0),"") | AX6: =IFERROR(VLOOKUP($A$6&$D$5&$B6&$AW$4,TKB_LOP_CHECK!$B$65:$J$860,9,0),"") | AY6: =IFERROR(VLOOKUP($A$6&$C$5&$B6&$AY$4,TKB_LOP_CHECK!$B$65:$J$860,9,0),"") | AZ6: =IFERROR(VLOOKUP($A$6&$D$5&$B6&$AY$4,TKB_LOP_CHECK!$B$65:$J$860,9,0),"") | BA6: =IFERROR(VLOOKUP($A$6&$C$5&$B6&$BA$4,TKB_LOP_CHECK!$B$65:$J$860,9,0),"") | BB6: =IFERROR(VLOOKUP($A$6&$D$5&$B6&$BA$4,TKB_LOP_CHECK!$B$65:$J$860,9,0),"") | BC6: =IFERROR(VLOOKUP($A$6&$C$5&$B6&$BC$4,TKB_LOP_CHECK!$B$65:$J$860,9,0),"") | BD6: =IFERROR(VLOOKUP($A$6&$D$5&$B6&$BC$4,TKB_LOP_CHECK!$B$65:$J$860,9,0),"") | BE6: =IFERROR(VLOOKUP($A$6&$C$5&$B6&$BE$4,TKB_LOP_CHECK!$B$65:$J$860,9,0),"") | BF6: =IFERROR(VLOOKUP($A$6&$D$5&$B6&$BE$4,TKB_LOP_CHECK!$B$65:$J$860,9,0),"") | BG6: =IFERROR(VLOOKUP($A$6&$C$5&$B6&$BG$4,TKB_LOP_CHECK!$B$65:$J$860,9,0),"") | BH6: =IFERROR(VLOOKUP($A$6&$D$5&$B6&$BG$4,TKB_LOP_CHECK!$B$65:$J$860,9,0),"") | BI6: =IFERROR(VLOOKUP($A$6&$C$5&$B6&$BI$4,TKB_LOP_CHECK!$B$65:$J$860,9,0),"") | BJ6: =IFERROR(VLOOKUP($A$6&$D$5&$B6&$BI$4,TKB_LOP_CHECK!$B$65:$J$860,9,0),"") | BK6: =IFERROR(VLOOKUP($A$6&$C$5&$B6&$BK$4,TKB_LOP_CHECK!$B$65:$J$860,9,0),"") | BL6: =IFERROR(VLOOKUP($A$6&$D$5&$B6&$BK$4,TKB_LOP_CHECK!$B$65:$J$860,9,0),"") | BM6: =IFERROR(VLOOKUP($A$6&$C$5&$B6&$BM$4,TKB_LOP_CHECK!$B$65:$J$860,9,0),"") | BN6: =IFERROR(VLOOKUP($A$6&$D$5&$B6&$BM$4,TKB_LOP_CHECK!$B$65:$J$860,9,0),"") | BO6: =IFERROR(VLOOKUP($A$6&$C$5&$B6&$BO$4,TKB_LOP_CHECK!$A$65:$J$860,10,0),"") | BP6: =IFERROR(VLOOKUP($A$6&$D$5&$B6&$BO$4,TKB_LOP_CHECK!$A$65:$J$860,10,0),"") | BQ6: =IFERROR(VLOOKUP($A$6&$C$5&$B6&$BQ$4,TKB_LOP_CHECK!$A$65:$J$860,10,0),"") | BR6: =IFERROR(VLOOKUP($A$6&$D$5&$B6&$BQ$4,TKB_LOP_CHECK!$A$65:$J$860,10,0),"") -> GVNN -2C1 | BS6: =IFERROR(VLOOKUP($A$6&$C$5&$B6&$BS$4,TKB_LOP_CHECK!$A$65:$J$860,10,0),"") | BT6: =IFERROR(VLOOKUP($A$6&$D$5&$B6&$BS$4,TKB_LOP_CHECK!$A$65:$J$860,10,0),"") | BU6: =IFERROR(VLOOKUP($A$6&$C$5&$B6&$BU$4,TKB_LOP_CHECK!$A$65:$J$860,10,0),"") | BV6: =IFERROR(VLOOKUP($A$6&$D$5&$B6&$BU$4,TKB_LOP_CHECK!$A$65:$J$860,10,0),"")
B7: 2 | C7: =IFERROR(VLOOKUP($A$6&$C$5&$B7&$C$4,TKB_LOP_CHECK!$B$65:$J$860,9,0),"") -> GVVN -6A1 | D7: =IFERROR(VLOOKUP($A$6&$D$5&$B7&$C$4,TKB_LOP_CHECK!$B$65:$J$860,9,0),"") | E7: =IFERROR(VLOOKUP($A$6&$C$5&$B7&$E$4,TKB_LOP_CHECK!$B$65:$J$860,9,0),"") | F7: =IFERROR(VLOOKUP($A$6&$D$5&$B7&$E$4,TKB_LOP_CHECK!$B$65:$J$860,9,0),"") -> Tiếng Trung -8A1 | G7: =IFERROR(VLOOKUP($A$6&$C$5&$B7&$G$4,TKB_LOP_CHECK!$B$65:$J$860,9,0),"") -> GVVN -8A1 | H7: =IFERROR(VLOOKUP($A$6&$D$5&$B7&$G$4,TKB_LOP_CHECK!$B$65:$J$860,9,0),"") | I7: =IFERROR(VLOOKUP($A$6&$C$5&$B7&$I$4,TKB_LOP_CHECK!$B$65:$J$860,9,0),"") -> Toán -3C1 | J7: =IFERROR(VLOOKUP($A$6&$D$5&$B7&$I$4,TKB_LOP_CHECK!$B$65:$J$860,9,0),"") | K7: =IFERROR(VLOOKUP($A$6&$C$5&$B7&$K$4,TKB_LOP_CHECK!$B$65:$J$860,9,0),"") -> Toán -3C1 | L7: =IFERROR(VLOOKUP($A$6&$D$5&$B7&$K$4,TKB_LOP_CHECK!$B$65:$J$860,9,0),"") | M7: =IFERROR(VLOOKUP($A$6&$C$5&$B7&$M$4,TKB_LOP_CHECK!$B$65:$J$860,9,0),"") -> GVVN -1A1 | N7: =IFERROR(VLOOKUP($A$6&$D$5&$B7&$M$4,TKB_LOP_CHECK!$B$65:$J$860,9,0),"") -> GVVN -TTH2 | O7: =IFERROR(VLOOKUP($A$6&$C$5&$B7&$O$4,TKB_LOP_CHECK!$B$65:$J$860,9,0),"") -> Đọc sách -TTH1 | P7: =IFERROR(VLOOKUP($A$6&$D$5&$B7&$O$4,TKB_LOP_CHECK!$B$65:$J$860,9,0),"") -> TViệt -TTH1 | Q7: =IFERROR(VLOOKUP($A$6&$C$5&$B7&$Q$4,TKB_LOP_CHECK!$B$65:$J$860,9,0),"") | R7: =IFERROR(VLOOKUP($A$6&$D$5&$B7&$Q$4,TKB_LOP_CHECK!$B$65:$J$860,9,0),"") -> GDTC -3A1 | S7: =IFERROR(VLOOKUP($A$6&$C$5&$B7&$S$4,TKB_LOP_CHECK!$B$65:$J$860,9,0),"") -> GVVN -8A1 | T7: =IFERROR(VLOOKUP($A$6&$D$5&$B7&$S$4,TKB_LOP_CHECK!$B$65:$J$860,9,0),"") | U7: =IFERROR(VLOOKUP($A$6&$C$5&$B7&$U$4,TKB_LOP_CHECK!$B$65:$J$860,9,0),"") | V7: =IFERROR(VLOOKUP($A$6&$D$5&$B7&$U$4,TKB_LOP_CHECK!$B$65:$J$860,9,0),"") -> Văn -7A1 | W7: =IFERROR(VLOOKUP($A$6&$C$5&$B7&$W$4,TKB_LOP_CHECK!$B$65:$J$860,9,0),"") | X7: =IFERROR(VLOOKUP($A$6&$D$5&$B7&$W$4,TKB_LOP_CHECK!$B$65:$J$860,9,0),"") | Y7: =IFERROR(VLOOKUP($A$6&$C$5&$B7&$Y$4,TKB_LOP_CHECK!$B$65:$J$860,9,0),"") | Z7: =IFERROR(VLOOKUP($A$6&$D$5&$B7&$Y$4,TKB_LOP_CHECK!$B$65:$J$860,9,0),"") | AA7: =IFERROR(VLOOKUP($A$6&$C$5&$B7&$AA$4,TKB_LOP_CHECK!$B$65:$J$860,9,0),"") -> GVVN -1A1 | AB7: =IFERROR(VLOOKUP($A$6&$D$5&$B7&$AA$4,TKB_LOP_CHECK!$B$65:$J$860,9,0),"") -> GVVN -TTH2 | AC7: =IFERROR(VLOOKUP($A$6&$C$5&$B7&$AC$4,TKB_LOP_CHECK!$B$65:$J$860,9,0),"") | AD7: =IFERROR(VLOOKUP($A$6&$D$5&$B7&$AC$4,TKB_LOP_CHECK!$B$65:$J$860,9,0),"") | AE7: =IFERROR(VLOOKUP($A$6&$C$5&$B7&$AE$4,TKB_LOP_CHECK!$B$65:$J$860,9,0),"") -> Science -5C1 | AF7: =IFERROR(VLOOKUP($A$6&$D$5&$B7&$AE$4,TKB_LOP_CHECK!$B$65:$J$860,9,0),"") -> GVNN -5C1 | AG7: =IFERROR(VLOOKUP($A$6&$C$5&$B7&$AG$4,TKB_LOP_CHECK!$B$65:$J$860,9,0),"") -> GVVN -1A1 | AH7: =IFERROR(VLOOKUP($A$6&$D$5&$B7&$AG$4,TKB_LOP_CHECK!$B$65:$J$860,9,0),"") -> GVVN -TTH2 | AI7: =IFERROR(VLOOKUP($A$6&$C$5&$B7&$AI$4,TKB_LOP_CHECK!$B$65:$J$860,9,0),"") | AJ7: =IFERROR(VLOOKUP($A$6&$D$5&$B7&$AI$4,TKB_LOP_CHECK!$B$65:$J$860,9,0),"") | AK7: =IFERROR(VLOOKUP($A$6&$C$5&$B7&$AK$4,TKB_LOP_CHECK!$B$65:$J$860,9,0),"") | AL7: =IFERROR(VLOOKUP($A$6&$D$5&$B7&$AK$4,TKB_LOP_CHECK!$B$65:$J$860,9,0),"") | AM7: =IFERROR(VLOOKUP($A$6&$C$5&$B7&$AM$4,TKB_LOP_CHECK!$B$65:$J$860,9,0),"") -> TViệt -4C1 | AN7: =IFERROR(VLOOKUP($A$6&$D$5&$B7&$AM$4,TKB_LOP_CHECK!$B$65:$J$860,9,0),"") -> TViệt -4C1 | AO7: =IFERROR(VLOOKUP($A$6&$C$5&$B7&$AO$4,TKB_LOP_CHECK!$B$65:$J$860,9,0),"") -> Viết sáng tạo -3A1 | AP7: =IFERROR(VLOOKUP($A$6&$D$5&$B7&$AO$4,TKB_LOP_CHECK!$B$65:$J$860,9,0),"") | AQ7: =IFERROR(VLOOKUP($A$6&$C$5&$B7&$AQ$4,TKB_LOP_CHECK!$B$65:$J$860,9,0),"") -> GVVN -6A1 | AR7: =IFERROR(VLOOKUP($A$6&$D$5&$B7&$AQ$4,TKB_LOP_CHECK!$B$65:$J$860,9,0),"") | AS7: =IFERROR(VLOOKUP($A$6&$C$5&$B7&$AS$4,TKB_LOP_CHECK!$B$65:$J$860,9,0),"") -> Toán -3C1 | AT7: =IFERROR(VLOOKUP($A$6&$D$5&$B7&$AS$4,TKB_LOP_CHECK!$B$65:$J$860,9,0),"") | AU7: =IFERROR(VLOOKUP($A$6&$C$5&$B7&$AU$4,TKB_LOP_CHECK!$B$65:$J$860,9,0),"") | AV7: =IFERROR(VLOOKUP($A$6&$D$5&$B7&$AU$4,TKB_LOP_CHECK!$B$65:$J$860,9,0),"") | AW7: =IFERROR(VLOOKUP($A$6&$C$5&$B7&$AW$4,TKB_LOP_CHECK!$B$65:$J$860,9,0),"") | AX7: =IFERROR(VLOOKUP($A$6&$D$5&$B7&$AW$4,TKB_LOP_CHECK!$B$65:$J$860,9,0),"") | AY7: =IFERROR(VLOOKUP($A$6&$C$5&$B7&$AY$4,TKB_LOP_CHECK!$B$65:$J$860,9,0),"") | AZ7: =IFERROR(VLOOKUP($A$6&$D$5&$B7&$AY$4,TKB_LOP_CHECK!$B$65:$J$860,9,0),"") | BA7: =IFERROR(VLOOKUP($A$6&$C$5&$B7&$BA$4,TKB_LOP_CHECK!$B$65:$J$860,9,0),"") | BB7: =IFERROR(VLOOKUP($A$6&$D$5&$B7&$BA$4,TKB_LOP_CHECK!$B$65:$J$860,9,0),"") | BC7: =IFERROR(VLOOKUP($A$6&$C$5&$B7&$BC$4,TKB_LOP_CHECK!$B$65:$J$860,9,0),"") | BD7: =IFERROR(VLOOKUP($A$6&$D$5&$B7&$BC$4,TKB_LOP_CHECK!$B$65:$J$860,9,0),"") | BE7: =IFERROR(VLOOKUP($A$6&$C$5&$B7&$BE$4,TKB_LOP_CHECK!$B$65:$J$860,9,0),"") | BF7: =IFERROR(VLOOKUP($A$6&$D$5&$B7&$BE$4,TKB_LOP_CHECK!$B$65:$J$860,9,0),"") | BG7: =IFERROR(VLOOKUP($A$6&$C$5&$B7&$BG$4,TKB_LOP_CHECK!$B$65:$J$860,9,0),"") | BH7: =IFERROR(VLOOKUP($A$6&$D$5&$B7&$BG$4,TKB_LOP_CHECK!$B$65:$J$860,9,0),"") | BI7: =IFERROR(VLOOKUP($A$6&$C$5&$B7&$BI$4,TKB_LOP_CHECK!$B$65:$J$860,9,0),"") | BJ7: =IFERROR(VLOOKUP($A$6&$D$5&$B7&$BI$4,TKB_LOP_CHECK!$B$65:$J$860,9,0),"") | BK7: =IFERROR(VLOOKUP($A$6&$C$5&$B7&$BK$4,TKB_LOP_CHECK!$B$65:$J$860,9,0),"") | BL7: =IFERROR(VLOOKUP($A$6&$D$5&$B7&$BK$4,TKB_LOP_CHECK!$B$65:$J$860,9,0),"") | BM7: =IFERROR(VLOOKUP($A$6&$C$5&$B7&$BM$4,TKB_LOP_CHECK!$B$65:$J$860,9,0),"") | BN7: =IFERROR(VLOOKUP($A$6&$D$5&$B7&$BM$4,TKB_LOP_CHECK!$B$65:$J$860,9,0),"") | BO7: =IFERROR(VLOOKUP($A$6&$C$5&$B7&$BO$4,TKB_LOP_CHECK!$A$65:$J$860,10,0),"") | BP7: =IFERROR(VLOOKUP($A$6&$D$5&$B7&$BO$4,TKB_LOP_CHECK!$A$65:$J$860,10,0),"") | BQ7: =IFERROR(VLOOKUP($A$6&$C$5&$B7&$BQ$4,TKB_LOP_CHECK!$A$65:$J$860,10,0),"") -> GVNN -1C1 | BR7: =IFERROR(VLOOKUP($A$6&$D$5&$B7&$BQ$4,TKB_LOP_CHECK!$A$65:$J$860,10,0),"") -> GVNN -5C1 | BS7: =IFERROR(VLOOKUP($A$6&$C$5&$B7&$BS$4,TKB_LOP_CHECK!$A$65:$J$860,10,0),"") | BT7: =IFERROR(VLOOKUP($A$6&$D$5&$B7&$BS$4,TKB_LOP_CHECK!$A$65:$J$860,10,0),"") | BU7: =IFERROR(VLOOKUP($A$6&$C$5&$B7&$BU$4,TKB_LOP_CHECK!$A$65:$J$860,10,0),"") | BV7: =IFERROR(VLOOKUP($A$6&$D$5&$B7&$BU$4,TKB_LOP_CHECK!$A$65:$J$860,10,0),"")
B8: 3 | C8: =IFERROR(VLOOKUP($A$6&$C$5&$B8&$C$4,TKB_LOP_CHECK!$B$65:$J$860,9,0),"") -> GVNN -6A1 | D8: =IFERROR(VLOOKUP($A$6&$D$5&$B8&$C$4,TKB_LOP_CHECK!$B$65:$J$860,9,0),"") | E8: =IFERROR(VLOOKUP($A$6&$C$5&$B8&$E$4,TKB_LOP_CHECK!$B$65:$J$860,9,0),"") | F8: =IFERROR(VLOOKUP($A$6&$D$5&$B8&$E$4,TKB_LOP_CHECK!$B$65:$J$860,9,0),"") -> Tiếng Trung -7A1 | G8: =IFERROR(VLOOKUP($A$6&$C$5&$B8&$G$4,TKB_LOP_CHECK!$B$65:$J$860,9,0),"") | H8: =IFERROR(VLOOKUP($A$6&$D$5&$B8&$G$4,TKB_LOP_CHECK!$B$65:$J$860,9,0),"") -> GVNN -8A1 | I8: =IFERROR(VLOOKUP($A$6&$C$5&$B8&$I$4,TKB_LOP_CHECK!$B$65:$J$860,9,0),"") -> Toán -5C1 | J8: =IFERROR(VLOOKUP($A$6&$D$5&$B8&$I$4,TKB_LOP_CHECK!$B$65:$J$860,9,0),"") -> Toán -5C1 | K8: =IFERROR(VLOOKUP($A$6&$C$5&$B8&$K$4,TKB_LOP_CHECK!$B$65:$J$860,9,0),"") -> Toán -5C1 | L8: =IFERROR(VLOOKUP($A$6&$D$5&$B8&$K$4,TKB_LOP_CHECK!$B$65:$J$860,9,0),"") -> Toán -5C1 | M8: =IFERROR(VLOOKUP($A$6&$C$5&$B8&$M$4,TKB_LOP_CHECK!$B$65:$J$860,9,0),"") | N8: =IFERROR(VLOOKUP($A$6&$D$5&$B8&$M$4,TKB_LOP_CHECK!$B$65:$J$860,9,0),"") -> GVVN -2A1 | O8: =IFERROR(VLOOKUP($A$6&$C$5&$B8&$O$4,TKB_LOP_CHECK!$B$65:$J$860,9,0),"") | P8: =IFERROR(VLOOKUP($A$6&$D$5&$B8&$O$4,TKB_LOP_CHECK!$B$65:$J$860,9,0),"") | Q8: =IFERROR(VLOOKUP($A$6&$C$5&$B8&$Q$4,TKB_LOP_CHECK!$B$65:$J$860,9,0),"") -> GDTC -TTH2 | R8: =IFERROR(VLOOKUP($A$6&$D$5&$B8&$Q$4,TKB_LOP_CHECK!$B$65:$J$860,9,0),"") -> GDTC -TTH1 | S8: =IFERROR(VLOOKUP($A$6&$C$5&$B8&$S$4,TKB_LOP_CHECK!$B$65:$J$860,9,0),"") | T8: =IFERROR(VLOOKUP($A$6&$D$5&$B8&$S$4,TKB_LOP_CHECK!$B$65:$J$860,9,0),"") -> GVNN -8A1 | U8: =IFERROR(VLOOKUP($A$6&$C$5&$B8&$U$4,TKB_LOP_CHECK!$B$65:$J$860,9,0),"") | V8: =IFERROR(VLOOKUP($A$6&$D$5&$B8&$U$4,TKB_LOP_CHECK!$B$65:$J$860,9,0),"") | W8: =IFERROR(VLOOKUP($A$6&$C$5&$B8&$W$4,TKB_LOP_CHECK!$B$65:$J$860,9,0),"") | X8: =IFERROR(VLOOKUP($A$6&$D$5&$B8&$W$4,TKB_LOP_CHECK!$B$65:$J$860,9,0),"") | Y8: =IFERROR(VLOOKUP($A$6&$C$5&$B8&$Y$4,TKB_LOP_CHECK!$B$65:$J$860,9,0),"") -> TViệt -3A1 | Z8: =IFERROR(VLOOKUP($A$6&$D$5&$B8&$Y$4,TKB_LOP_CHECK!$B$65:$J$860,9,0),"") | AA8: =IFERROR(VLOOKUP($A$6&$C$5&$B8&$AA$4,TKB_LOP_CHECK!$B$65:$J$860,9,0),"") | AB8: =IFERROR(VLOOKUP($A$6&$D$5&$B8&$AA$4,TKB_LOP_CHECK!$B$65:$J$860,9,0),"") -> GVVN -2A1 | AC8: =IFERROR(VLOOKUP($A$6&$C$5&$B8&$AC$4,TKB_LOP_CHECK!$B$65:$J$860,9,0),"") | AD8: =IFERROR(VLOOKUP($A$6&$D$5&$B8&$AC$4,TKB_LOP_CHECK!$B$65:$J$860,9,0),"") | AE8: =IFERROR(VLOOKUP($A$6&$C$5&$B8&$AE$4,TKB_LOP_CHECK!$B$65:$J$860,9,0),"") | AF8: =IFERROR(VLOOKUP($A$6&$D$5&$B8&$AE$4,TKB_LOP_CHECK!$B$65:$J$860,9,0),"") -> Science -3C1 | AG8: =IFERROR(VLOOKUP($A$6&$C$5&$B8&$AG$4,TKB_LOP_CHECK!$B$65:$J$860,9,0),"") | AH8: =IFERROR(VLOOKUP($A$6&$D$5&$B8&$AG$4,TKB_LOP_CHECK!$B$65:$J$860,9,0),"") -> GVVN -2A1 | AI8: =IFERROR(VLOOKUP($A$6&$C$5&$B8&$AI$4,TKB_LOP_CHECK!$B$65:$J$860,9,0),"") | AJ8: =IFERROR(VLOOKUP($A$6&$D$5&$B8&$AI$4,TKB_LOP_CHECK!$B$65:$J$860,9,0),"") | AK8: =IFERROR(VLOOKUP($A$6&$C$5&$B8&$AK$4,TKB_LOP_CHECK!$B$65:$J$860,9,0),"") | AL8: =IFERROR(VLOOKUP($A$6&$D$5&$B8&$AK$4,TKB_LOP_CHECK!$B$65:$J$860,9,0),"") | AM8: =IFERROR(VLOOKUP($A$6&$C$5&$B8&$AM$4,TKB_LOP_CHECK!$B$65:$J$860,9,0),"") -> TViệt -3C1 | AN8: =IFERROR(VLOOKUP($A$6&$D$5&$B8&$AM$4,TKB_LOP_CHECK!$B$65:$J$860,9,0),"") | AO8: =IFERROR(VLOOKUP($A$6&$C$5&$B8&$AO$4,TKB_LOP_CHECK!$B$65:$J$860,9,0),"") -> TViệt -2C1 | AP8: =IFERROR(VLOOKUP($A$6&$D$5&$B8&$AO$4,TKB_LOP_CHECK!$B$65:$J$860,9,0),"") -> Viết sáng tạo -2C1 | AQ8: =IFERROR(VLOOKUP($A$6&$C$5&$B8&$AQ$4,TKB_LOP_CHECK!$B$65:$J$860,9,0),"") -> GVNN -6A1 | AR8: =IFERROR(VLOOKUP($A$6&$D$5&$B8&$AQ$4,TKB_LOP_CHECK!$B$65:$J$860,9,0),"") | AS8: =IFERROR(VLOOKUP($A$6&$C$5&$B8&$AS$4,TKB_LOP_CHECK!$B$65:$J$860,9,0),"") -> Toán -5C1 | AT8: =IFERROR(VLOOKUP($A$6&$D$5&$B8&$AS$4,TKB_LOP_CHECK!$B$65:$J$860,9,0),"") -> Toán -5C1 | AU8: =IFERROR(VLOOKUP($A$6&$C$5&$B8&$AU$4,TKB_LOP_CHECK!$B$65:$J$860,9,0),"") | AV8: =IFERROR(VLOOKUP($A$6&$D$5&$B8&$AU$4,TKB_LOP_CHECK!$B$65:$J$860,9,0),"") | AW8: =IFERROR(VLOOKUP($A$6&$C$5&$B8&$AW$4,TKB_LOP_CHECK!$B$65:$J$860,9,0),"") | AX8: =IFERROR(VLOOKUP($A$6&$D$5&$B8&$AW$4,TKB_LOP_CHECK!$B$65:$J$860,9,0),"") | AY8: =IFERROR(VLOOKUP($A$6&$C$5&$B8&$AY$4,TKB_LOP_CHECK!$B$65:$J$860,9,0),"") | AZ8: =IFERROR(VLOOKUP($A$6&$D$5&$B8&$AY$4,TKB_LOP_CHECK!$B$65:$J$860,9,0),"") | BA8: =IFERROR(VLOOKUP($A$6&$C$5&$B8&$BA$4,TKB_LOP_CHECK!$B$65:$J$860,9,0),"") | BB8: =IFERROR(VLOOKUP($A$6&$D$5&$B8&$BA$4,TKB_LOP_CHECK!$B$65:$J$860,9,0),"") | BC8: =IFERROR(VLOOKUP($A$6&$C$5&$B8&$BC$4,TKB_LOP_CHECK!$B$65:$J$860,9,0),"") | BD8: =IFERROR(VLOOKUP($A$6&$D$5&$B8&$BC$4,TKB_LOP_CHECK!$B$65:$J$860,9,0),"") | BE8: =IFERROR(VLOOKUP($A$6&$C$5&$B8&$BE$4,TKB_LOP_CHECK!$B$65:$J$860,9,0),"") | BF8: =IFERROR(VLOOKUP($A$6&$D$5&$B8&$BE$4,TKB_LOP_CHECK!$B$65:$J$860,9,0),"") | BG8: =IFERROR(VLOOKUP($A$6&$C$5&$B8&$BG$4,TKB_LOP_CHECK!$B$65:$J$860,9,0),"") | BH8: =IFERROR(VLOOKUP($A$6&$D$5&$B8&$BG$4,TKB_LOP_CHECK!$B$65:$J$860,9,0),"") | BI8: =IFERROR(VLOOKUP($A$6&$C$5&$B8&$BI$4,TKB_LOP_CHECK!$B$65:$J$860,9,0),"") | BJ8: =IFERROR(VLOOKUP($A$6&$D$5&$B8&$BI$4,TKB_LOP_CHECK!$B$65:$J$860,9,0),"") | BK8: =IFERROR(VLOOKUP($A$6&$C$5&$B8&$BK$4,TKB_LOP_CHECK!$B$65:$J$860,9,0),"") | BL8: =IFERROR(VLOOKUP($A$6&$D$5&$B8&$BK$4,TKB_LOP_CHECK!$B$65:$J$860,9,0),"") | BM8: =IFERROR(VLOOKUP($A$6&$C$5&$B8&$BM$4,TKB_LOP_CHECK!$B$65:$J$860,9,0),"") | BN8: =IFERROR(VLOOKUP($A$6&$D$5&$B8&$BM$4,TKB_LOP_CHECK!$B$65:$J$860,9,0),"") | BO8: =IFERROR(VLOOKUP($A$6&$C$5&$B8&$BO$4,TKB_LOP_CHECK!$A$65:$J$860,10,0),"") | BP8: =IFERROR(VLOOKUP($A$6&$D$5&$B8&$BO$4,TKB_LOP_CHECK!$A$65:$J$860,10,0),"") | BQ8: =IFERROR(VLOOKUP($A$6&$C$5&$B8&$BQ$4,TKB_LOP_CHECK!$A$65:$J$860,10,0),"") -> GVNN -6A1 | BR8: =IFERROR(VLOOKUP($A$6&$D$5&$B8&$BQ$4,TKB_LOP_CHECK!$A$65:$J$860,10,0),"") -> GVNN -8A1 | BS8: =IFERROR(VLOOKUP($A$6&$C$5&$B8&$BS$4,TKB_LOP_CHECK!$A$65:$J$860,10,0),"") | BT8: =IFERROR(VLOOKUP($A$6&$D$5&$B8&$BS$4,TKB_LOP_CHECK!$A$65:$J$860,10,0),"") | BU8: =IFERROR(VLOOKUP($A$6&$C$5&$B8&$BU$4,TKB_LOP_CHECK!$A$65:$J$860,10,0),"") | BV8: =IFERROR(VLOOKUP($A$6&$D$5&$B8&$BU$4,TKB_LOP_CHECK!$A$65:$J$860,10,0),"")
B9: 4 | C9: =IFERROR(VLOOKUP($A$6&$C$5&$B9&$C$4,TKB_LOP_CHECK!$B$65:$J$860,9,0),"") -> GVVN -7A1 | D9: =IFERROR(VLOOKUP($A$6&$D$5&$B9&$C$4,TKB_LOP_CHECK!$B$65:$J$860,9,0),"") | E9: =IFERROR(VLOOKUP($A$6&$C$5&$B9&$E$4,TKB_LOP_CHECK!$B$65:$J$860,9,0),"") | F9: =IFERROR(VLOOKUP($A$6&$D$5&$B9&$E$4,TKB_LOP_CHECK!$B$65:$J$860,9,0),"") -> Tiếng Trung -6A1 | G9: =IFERROR(VLOOKUP($A$6&$C$5&$B9&$G$4,TKB_LOP_CHECK!$B$65:$J$860,9,0),"") -> GVNN -4C1 | H9: =IFERROR(VLOOKUP($A$6&$D$5&$B9&$G$4,TKB_LOP_CHECK!$B$65:$J$860,9,0),"") | I9: =IFERROR(VLOOKUP($A$6&$C$5&$B9&$I$4,TKB_LOP_CHECK!$B$65:$J$860,9,0),"") -> Toán -3C1 | J9: =IFERROR(VLOOKUP($A$6&$D$5&$B9&$I$4,TKB_LOP_CHECK!$B$65:$J$860,9,0),"") | K9: =IFERROR(VLOOKUP($A$6&$C$5&$B9&$K$4,TKB_LOP_CHECK!$B$65:$J$860,9,0),"") -> Toán -3C1 | L9: =IFERROR(VLOOKUP($A$6&$D$5&$B9&$K$4,TKB_LOP_CHECK!$B$65:$J$860,9,0),"") | M9: =IFERROR(VLOOKUP($A$6&$C$5&$B9&$M$4,TKB_LOP_CHECK!$B$65:$J$860,9,0),"") -> GVVN -2A1 | N9: =IFERROR(VLOOKUP($A$6&$D$5&$B9&$M$4,TKB_LOP_CHECK!$B$65:$J$860,9,0),"") | O9: =IFERROR(VLOOKUP($A$6&$C$5&$B9&$O$4,TKB_LOP_CHECK!$B$65:$J$860,9,0),"") | P9: =IFERROR(VLOOKUP($A$6&$D$5&$B9&$O$4,TKB_LOP_CHECK!$B$65:$J$860,9,0),"") | Q9: =IFERROR(VLOOKUP($A$6&$C$5&$B9&$Q$4,TKB_LOP_CHECK!$B$65:$J$860,9,0),"") -> GDTC -TTH2 | R9: =IFERROR(VLOOKUP($A$6&$D$5&$B9&$Q$4,TKB_LOP_CHECK!$B$65:$J$860,9,0),"") -> GDTC -TTH1 | S9: =IFERROR(VLOOKUP($A$6&$C$5&$B9&$S$4,TKB_LOP_CHECK!$B$65:$J$860,9,0),"") -> GVNN -4C1 | T9: =IFERROR(VLOOKUP($A$6&$D$5&$B9&$S$4,TKB_LOP_CHECK!$B$65:$J$860,9,0),"") | U9: =IFERROR(VLOOKUP($A$6&$C$5&$B9&$U$4,TKB_LOP_CHECK!$B$65:$J$860,9,0),"") -> Văn -8A1 | V9: =IFERROR(VLOOKUP($A$6&$D$5&$B9&$U$4,TKB_LOP_CHECK!$B$65:$J$860,9,0),"") | W9: =IFERROR(VLOOKUP($A$6&$C$5&$B9&$W$4,TKB_LOP_CHECK!$B$65:$J$860,9,0),"") | X9: =IFERROR(VLOOKUP($A$6&$D$5&$B9&$W$4,TKB_LOP_CHECK!$B$65:$J$860,9,0),"") | Y9: =IFERROR(VLOOKUP($A$6&$C$5&$B9&$Y$4,TKB_LOP_CHECK!$B$65:$J$860,9,0),"") -> TViệt -5C1 | Z9: =IFERROR(VLOOKUP($A$6&$D$5&$B9&$Y$4,TKB_LOP_CHECK!$B$65:$J$860,9,0),"") -> TViệt -5C1 | AA9: =IFERROR(VLOOKUP($A$6&$C$5&$B9&$AA$4,TKB_LOP_CHECK!$B$65:$J$860,9,0),"") -> GVVN -2A1 | AB9: =IFERROR(VLOOKUP($A$6&$D$5&$B9&$AA$4,TKB_LOP_CHECK!$B$65:$J$860,9,0),"") | AC9: =IFERROR(VLOOKUP($A$6&$C$5&$B9&$AC$4,TKB_LOP_CHECK!$B$65:$J$860,9,0),"") | AD9: =IFERROR(VLOOKUP($A$6&$D$5&$B9&$AC$4,TKB_LOP_CHECK!$B$65:$J$860,9,0),"") | AE9: =IFERROR(VLOOKUP($A$6&$C$5&$B9&$AE$4,TKB_LOP_CHECK!$B$65:$J$860,9,0),"") | AF9: =IFERROR(VLOOKUP($A$6&$D$5&$B9&$AE$4,TKB_LOP_CHECK!$B$65:$J$860,9,0),"") -> GVNN -3C1 | AG9: =IFERROR(VLOOKUP($A$6&$C$5&$B9&$AG$4,TKB_LOP_CHECK!$B$65:$J$860,9,0),"") -> GVVN -2A1 | AH9: =IFERROR(VLOOKUP($A$6&$D$5&$B9&$AG$4,TKB_LOP_CHECK!$B$65:$J$860,9,0),"") | AI9: =IFERROR(VLOOKUP($A$6&$C$5&$B9&$AI$4,TKB_LOP_CHECK!$B$65:$J$860,9,0),"") | AJ9: =IFERROR(VLOOKUP($A$6&$D$5&$B9&$AI$4,TKB_LOP_CHECK!$B$65:$J$860,9,0),"") | AK9: =IFERROR(VLOOKUP($A$6&$C$5&$B9&$AK$4,TKB_LOP_CHECK!$B$65:$J$860,9,0),"") | AL9: =IFERROR(VLOOKUP($A$6&$D$5&$B9&$AK$4,TKB_LOP_CHECK!$B$65:$J$860,9,0),"") | AM9: =IFERROR(VLOOKUP($A$6&$C$5&$B9&$AM$4,TKB_LOP_CHECK!$B$65:$J$860,9,0),"") | AN9: =IFERROR(VLOOKUP($A$6&$D$5&$B9&$AM$4,TKB_LOP_CHECK!$B$65:$J$860,9,0),"") -> Đạo đức -4C1 | AO9: =IFERROR(VLOOKUP($A$6&$C$5&$B9&$AO$4,TKB_LOP_CHECK!$B$65:$J$860,9,0),"") -> TViệt -2C1 | AP9: =IFERROR(VLOOKUP($A$6&$D$5&$B9&$AO$4,TKB_LOP_CHECK!$B$65:$J$860,9,0),"") | AQ9: =IFERROR(VLOOKUP($A$6&$C$5&$B9&$AQ$4,TKB_LOP_CHECK!$B$65:$J$860,9,0),"") -> GVVN -7A1 | AR9: =IFERROR(VLOOKUP($A$6&$D$5&$B9&$AQ$4,TKB_LOP_CHECK!$B$65:$J$860,9,0),"") | AS9: =IFERROR(VLOOKUP($A$6&$C$5&$B9&$AS$4,TKB_LOP_CHECK!$B$65:$J$860,9,0),"") -> Toán -3C1 | AT9: =IFERROR(VLOOKUP($A$6&$D$5&$B9&$AS$4,TKB_LOP_CHECK!$B$65:$J$860,9,0),"") | AU9: =IFERROR(VLOOKUP($A$6&$C$5&$B9&$AU$4,TKB_LOP_CHECK!$B$65:$J$860,9,0),"") | AV9: =IFERROR(VLOOKUP($A$6&$D$5&$B9&$AU$4,TKB_LOP_CHECK!$B$65:$J$860,9,0),"") | AW9: =IFERROR(VLOOKUP($A$6&$C$5&$B9&$AW$4,TKB_LOP_CHECK!$B$65:$J$860,9,0),"") | AX9: =IFERROR(VLOOKUP($A$6&$D$5&$B9&$AW$4,TKB_LOP_CHECK!$B$65:$J$860,9,0),"") | AY9: =IFERROR(VLOOKUP($A$6&$C$5&$B9&$AY$4,TKB_LOP_CHECK!$B$65:$J$860,9,0),"") | AZ9: =IFERROR(VLOOKUP($A$6&$D$5&$B9&$AY$4,TKB_LOP_CHECK!$B$65:$J$860,9,0),"") | BA9: =IFERROR(VLOOKUP($A$6&$C$5&$B9&$BA$4,TKB_LOP_CHECK!$B$65:$J$860,9,0),"") | BB9: =IFERROR(VLOOKUP($A$6&$D$5&$B9&$BA$4,TKB_LOP_CHECK!$B$65:$J$860,9,0),"") | BC9: =IFERROR(VLOOKUP($A$6&$C$5&$B9&$BC$4,TKB_LOP_CHECK!$B$65:$J$860,9,0),"") | BD9: =IFERROR(VLOOKUP($A$6&$D$5&$B9&$BC$4,TKB_LOP_CHECK!$B$65:$J$860,9,0),"") | BE9: =IFERROR(VLOOKUP($A$6&$C$5&$B9&$BE$4,TKB_LOP_CHECK!$B$65:$J$860,9,0),"") | BF9: =IFERROR(VLOOKUP($A$6&$D$5&$B9&$BE$4,TKB_LOP_CHECK!$B$65:$J$860,9,0),"") | BG9: =IFERROR(VLOOKUP($A$6&$C$5&$B9&$BG$4,TKB_LOP_CHECK!$B$65:$J$860,9,0),"") | BH9: =IFERROR(VLOOKUP($A$6&$D$5&$B9&$BG$4,TKB_LOP_CHECK!$B$65:$J$860,9,0),"") | BI9: =IFERROR(VLOOKUP($A$6&$C$5&$B9&$BI$4,TKB_LOP_CHECK!$B$65:$J$860,9,0),"") | BJ9: =IFERROR(VLOOKUP($A$6&$D$5&$B9&$BI$4,TKB_LOP_CHECK!$B$65:$J$860,9,0),"") | BK9: =IFERROR(VLOOKUP($A$6&$C$5&$B9&$BK$4,TKB_LOP_CHECK!$B$65:$J$860,9,0),"") | BL9: =IFERROR(VLOOKUP($A$6&$D$5&$B9&$BK$4,TKB_LOP_CHECK!$B$65:$J$860,9,0),"") | BM9: =IFERROR(VLOOKUP($A$6&$C$5&$B9&$BM$4,TKB_LOP_CHECK!$B$65:$J$860,9,0),"") | BN9: =IFERROR(VLOOKUP($A$6&$D$5&$B9&$BM$4,TKB_LOP_CHECK!$B$65:$J$860,9,0),"") | BO9: =IFERROR(VLOOKUP($A$6&$C$5&$B9&$BO$4,TKB_LOP_CHECK!$A$65:$J$860,10,0),"") | BP9: =IFERROR(VLOOKUP($A$6&$D$5&$B9&$BO$4,TKB_LOP_CHECK!$A$65:$J$860,10,0),"") | BQ9: =IFERROR(VLOOKUP($A$6&$C$5&$B9&$BQ$4,TKB_LOP_CHECK!$A$65:$J$860,10,0),"") -> GVNN -4C1 | BR9: =IFERROR(VLOOKUP($A$6&$D$5&$B9&$BQ$4,TKB_LOP_CHECK!$A$65:$J$860,10,0),"") -> GVNN -3C1 | BS9: =IFERROR(VLOOKUP($A$6&$C$5&$B9&$BS$4,TKB_LOP_CHECK!$A$65:$J$860,10,0),"") | BT9: =IFERROR(VLOOKUP($A$6&$D$5&$B9&$BS$4,TKB_LOP_CHECK!$A$65:$J$860,10,0),"") | BU9: =IFERROR(VLOOKUP($A$6&$C$5&$B9&$BU$4,TKB_LOP_CHECK!$A$65:$J$860,10,0),"") | BV9: =IFERROR(VLOOKUP($A$6&$D$5&$B9&$BU$4,TKB_LOP_CHECK!$A$65:$J$860,10,0),"")
B10: 5 | C10: =IFERROR(VLOOKUP($A$6&$C$5&$B10&$C$4,TKB_LOP_CHECK!$B$65:$J$860,9,0),"") -> GVVN -7A1 | D10: =IFERROR(VLOOKUP($A$6&$D$5&$B10&$C$4,TKB_LOP_CHECK!$B$65:$J$860,9,0),"") | E10: =IFERROR(VLOOKUP($A$6&$C$5&$B10&$E$4,TKB_LOP_CHECK!$B$65:$J$860,9,0),"") | F10: =IFERROR(VLOOKUP($A$6&$D$5&$B10&$E$4,TKB_LOP_CHECK!$B$65:$J$860,9,0),"") | G10: =IFERROR(VLOOKUP($A$6&$C$5&$B10&$G$4,TKB_LOP_CHECK!$B$65:$J$860,9,0),"") | H10: =IFERROR(VLOOKUP($A$6&$D$5&$B10&$G$4,TKB_LOP_CHECK!$B$65:$J$860,9,0),"") | I10: =IFERROR(VLOOKUP($A$6&$C$5&$B10&$I$4,TKB_LOP_CHECK!$B$65:$J$860,9,0),"") | J10: =IFERROR(VLOOKUP($A$6&$D$5&$B10&$I$4,TKB_LOP_CHECK!$B$65:$J$860,9,0),"") | K10: =IFERROR(VLOOKUP($A$6&$C$5&$B10&$K$4,TKB_LOP_CHECK!$B$65:$J$860,9,0),"") | L10: =IFERROR(VLOOKUP($A$6&$D$5&$B10&$K$4,TKB_LOP_CHECK!$B$65:$J$860,9,0),"") | M10: =IFERROR(VLOOKUP($A$6&$C$5&$B10&$M$4,TKB_LOP_CHECK!$B$65:$J$860,9,0),"") | N10: =IFERROR(VLOOKUP($A$6&$D$5&$B10&$M$4,TKB_LOP_CHECK!$B$65:$J$860,9,0),"") | O10: =IFERROR(VLOOKUP($A$6&$C$5&$B10&$O$4,TKB_LOP_CHECK!$B$65:$J$860,9,0),"") | P10: =IFERROR(VLOOKUP($A$6&$D$5&$B10&$O$4,TKB_LOP_CHECK!$B$65:$J$860,9,0),"") | Q10: =IFERROR(VLOOKUP($A$6&$C$5&$B10&$Q$4,TKB_LOP_CHECK!$B$65:$J$860,9,0),"") | R10: =IFERROR(VLOOKUP($A$6&$D$5&$B10&$Q$4,TKB_LOP_CHECK!$B$65:$J$860,9,0),"") | S10: =IFERROR(VLOOKUP($A$6&$C$5&$B10&$S$4,TKB_LOP_CHECK!$B$65:$J$860,9,0),"") | T10: =IFERROR(VLOOKUP($A$6&$D$5&$B10&$S$4,TKB_LOP_CHECK!$B$65:$J$860,9,0),"") | U10: =IFERROR(VLOOKUP($A$6&$C$5&$B10&$U$4,TKB_LOP_CHECK!$B$65:$J$860,9,0),"") -> Văn -8A1 | V10: =IFERROR(VLOOKUP($A$6&$D$5&$B10&$U$4,TKB_LOP_CHECK!$B$65:$J$860,9,0),"") | W10: =IFERROR(VLOOKUP($A$6&$C$5&$B10&$W$4,TKB_LOP_CHECK!$B$65:$J$860,9,0),"") | X10: =IFERROR(VLOOKUP($A$6&$D$5&$B10&$W$4,TKB_LOP_CHECK!$B$65:$J$860,9,0),"") | Y10: =IFERROR(VLOOKUP($A$6&$C$5&$B10&$Y$4,TKB_LOP_CHECK!$B$65:$J$860,9,0),"") | Z10: =IFERROR(VLOOKUP($A$6&$D$5&$B10&$Y$4,TKB_LOP_CHECK!$B$65:$J$860,9,0),"") | AA10: =IFERROR(VLOOKUP($A$6&$C$5&$B10&$AA$4,TKB_LOP_CHECK!$B$65:$J$860,9,0),"") | AB10: =IFERROR(VLOOKUP($A$6&$D$5&$B10&$AA$4,TKB_LOP_CHECK!$B$65:$J$860,9,0),"") | AC10: =IFERROR(VLOOKUP($A$6&$C$5&$B10&$AC$4,TKB_LOP_CHECK!$B$65:$J$860,9,0),"") | AD10: =IFERROR(VLOOKUP($A$6&$D$5&$B10&$AC$4,TKB_LOP_CHECK!$B$65:$J$860,9,0),"") | AE10: =IFERROR(VLOOKUP($A$6&$C$5&$B10&$AE$4,TKB_LOP_CHECK!$B$65:$J$860,9,0),"") | AF10: =IFERROR(VLOOKUP($A$6&$D$5&$B10&$AE$4,TKB_LOP_CHECK!$B$65:$J$860,9,0),"") | AG10: =IFERROR(VLOOKUP($A$6&$C$5&$B10&$AG$4,TKB_LOP_CHECK!$B$65:$J$860,9,0),"") | AH10: =IFERROR(VLOOKUP($A$6&$D$5&$B10&$AG$4,TKB_LOP_CHECK!$B$65:$J$860,9,0),"") | AI10: =IFERROR(VLOOKUP($A$6&$C$5&$B10&$AI$4,TKB_LOP_CHECK!$B$65:$J$860,9,0),"") | AJ10: =IFERROR(VLOOKUP($A$6&$D$5&$B10&$AI$4,TKB_LOP_CHECK!$B$65:$J$860,9,0),"") | AK10: =IFERROR(VLOOKUP($A$6&$C$5&$B10&$AK$4,TKB_LOP_CHECK!$B$65:$J$860,9,0),"") | AL10: =IFERROR(VLOOKUP($A$6&$D$5&$B10&$AK$4,TKB_LOP_CHECK!$B$65:$J$860,9,0),"") | AM10: =IFERROR(VLOOKUP($A$6&$C$5&$B10&$AM$4,TKB_LOP_CHECK!$B$65:$J$860,9,0),"") | AN10: =IFERROR(VLOOKUP($A$6&$D$5&$B10&$AM$4,TKB_LOP_CHECK!$B$65:$J$860,9,0),"") | AO10: =IFERROR(VLOOKUP($A$6&$C$5&$B10&$AO$4,TKB_LOP_CHECK!$B$65:$J$860,9,0),"") | AP10: =IFERROR(VLOOKUP($A$6&$D$5&$B10&$AO$4,TKB_LOP_CHECK!$B$65:$J$860,9,0),"") | AQ10: =IFERROR(VLOOKUP($A$6&$C$5&$B10&$AQ$4,TKB_LOP_CHECK!$B$65:$J$860,9,0),"") -> GVVN -7A1 | AR10: =IFERROR(VLOOKUP($A$6&$D$5&$B10&$AQ$4,TKB_LOP_CHECK!$B$65:$J$860,9,0),"") | AS10: =IFERROR(VLOOKUP($A$6&$C$5&$B10&$AS$4,TKB_LOP_CHECK!$B$65:$J$860,9,0),"") | AT10: =IFERROR(VLOOKUP($A$6&$D$5&$B10&$AS$4,TKB_LOP_CHECK!$B$65:$J$860,9,0),"") | AU10: =IFERROR(VLOOKUP($A$6&$C$5&$B10&$AU$4,TKB_LOP_CHECK!$B$65:$J$860,9,0),"") | AV10: =IFERROR(VLOOKUP($A$6&$D$5&$B10&$AU$4,TKB_LOP_CHECK!$B$65:$J$860,9,0),"") | AW10: =IFERROR(VLOOKUP($A$6&$C$5&$B10&$AW$4,TKB_LOP_CHECK!$B$65:$J$860,9,0),"") | AX10: =IFERROR(VLOOKUP($A$6&$D$5&$B10&$AW$4,TKB_LOP_CHECK!$B$65:$J$860,9,0),"") | AY10: =IFERROR(VLOOKUP($A$6&$C$5&$B10&$AY$4,TKB_LOP_CHECK!$B$65:$J$860,9,0),"") | AZ10: =IFERROR(VLOOKUP($A$6&$D$5&$B10&$AY$4,TKB_LOP_CHECK!$B$65:$J$860,9,0),"") | BA10: =IFERROR(VLOOKUP($A$6&$C$5&$B10&$BA$4,TKB_LOP_CHECK!$B$65:$J$860,9,0),"") | BB10: =IFERROR(VLOOKUP($A$6&$D$5&$B10&$BA$4,TKB_LOP_CHECK!$B$65:$J$860,9,0),"") | BC10: =IFERROR(VLOOKUP($A$6&$C$5&$B10&$BC$4,TKB_LOP_CHECK!$B$65:$J$860,9,0),"") | BD10: =IFERROR(VLOOKUP($A$6&$D$5&$B10&$BC$4,TKB_LOP_CHECK!$B$65:$J$860,9,0),"") | BE10: =IFERROR(VLOOKUP($A$6&$C$5&$B10&$BE$4,TKB_LOP_CHECK!$B$65:$J$860,9,0),"") | BF10: =IFERROR(VLOOKUP($A$6&$D$5&$B10&$BE$4,TKB_LOP_CHECK!$B$65:$J$860,9,0),"") | BG10: =IFERROR(VLOOKUP($A$6&$C$5&$B10&$BG$4,TKB_LOP_CHECK!$B$65:$J$860,9,0),"") | BH10: =IFERROR(VLOOKUP($A$6&$D$5&$B10&$BG$4,TKB_LOP_CHECK!$B$65:$J$860,9,0),"") | BI10: =IFERROR(VLOOKUP($A$6&$C$5&$B10&$BI$4,TKB_LOP_CHECK!$B$65:$J$860,9,0),"") | BJ10: =IFERROR(VLOOKUP($A$6&$D$5&$B10&$BI$4,TKB_LOP_CHECK!$B$65:$J$860,9,0),"") | BK10: =IFERROR(VLOOKUP($A$6&$C$5&$B10&$BK$4,TKB_LOP_CHECK!$B$65:$J$860,9,0),"") | BL10: =IFERROR(VLOOKUP($A$6&$D$5&$B10&$BK$4,TKB_LOP_CHECK!$B$65:$J$860,9,0),"") | BM10: =IFERROR(VLOOKUP($A$6&$C$5&$B10&$BM$4,TKB_LOP_CHECK!$B$65:$J$860,9,0),"") | BN10: =IFERROR(VLOOKUP($A$6&$D$5&$B10&$BM$4,TKB_LOP_CHECK!$B$65:$J$860,9,0),"") | BO10: =IFERROR(VLOOKUP($A$6&$C$5&$B10&$BO$4,TKB_LOP_CHECK!$A$65:$J$860,10,0),"") | BP10: =IFERROR(VLOOKUP($A$6&$D$5&$B10&$BO$4,TKB_LOP_CHECK!$A$65:$J$860,10,0),"") | BQ10: =IFERROR(VLOOKUP($A$6&$C$5&$B10&$BQ$4,TKB_LOP_CHECK!$A$65:$J$860,10,0),"") | BR10: =IFERROR(VLOOKUP($A$6&$D$5&$B10&$BQ$4,TKB_LOP_CHECK!$A$65:$J$860,10,0),"") | BS10: =IFERROR(VLOOKUP($A$6&$C$5&$B10&$BS$4,TKB_LOP_CHECK!$A$65:$J$860,10,0),"") | BT10: =IFERROR(VLOOKUP($A$6&$D$5&$B10&$BS$4,TKB_LOP_CHECK!$A$65:$J$860,10,0),"") | BU10: =IFERROR(VLOOKUP($A$6&$C$5&$B10&$BU$4,TKB_LOP_CHECK!$A$65:$J$860,10,0),"") | BV10: =IFERROR(VLOOKUP($A$6&$D$5&$B10&$BU$4,TKB_LOP_CHECK!$A$65:$J$860,10,0),"")
A11: 3 | B11: 1 | C11: =IFERROR(VLOOKUP($A$11&$C$5&$B11&$C$4,TKB_LOP_CHECK!$B$65:$J$860,9,0),"") -> GVNN -7A1 | D11: =IFERROR(VLOOKUP($A$11&$D$5&$B11&$C$4,TKB_LOP_CHECK!$B$65:$J$860,9,0),"") -> GVNN -7A1 | E11: =IFERROR(VLOOKUP($A$11&$C$5&$B11&$E$4,TKB_LOP_CHECK!$B$65:$J$860,9,0),"") | F11: =IFERROR(VLOOKUP($A$11&$D$5&$B11&$E$4,TKB_LOP_CHECK!$B$65:$J$860,9,0),"") | G11: =IFERROR(VLOOKUP($A$11&$C$5&$B11&$G$4,TKB_LOP_CHECK!$B$65:$J$860,9,0),"") | H11: =IFERROR(VLOOKUP($A$11&$D$5&$B11&$G$4,TKB_LOP_CHECK!$B$65:$J$860,9,0),"") -> GVVN -4C1 | I11: =IFERROR(VLOOKUP($A$11&$C$5&$B11&$I$4,TKB_LOP_CHECK!$B$65:$J$860,9,0),"") -> Toán -2C1 | J11: =IFERROR(VLOOKUP($A$11&$D$5&$B11&$I$4,TKB_LOP_CHECK!$B$65:$J$860,9,0),"") -> Toán -3C1 | K11: =IFERROR(VLOOKUP($A$11&$C$5&$B11&$K$4,TKB_LOP_CHECK!$B$65:$J$860,9,0),"") -> Toán -2C1 | L11: =IFERROR(VLOOKUP($A$11&$D$5&$B11&$K$4,TKB_LOP_CHECK!$B$65:$J$860,9,0),"") -> Toán -3C1 | M11: =IFERROR(VLOOKUP($A$11&$C$5&$B11&$M$4,TKB_LOP_CHECK!$B$65:$J$860,9,0),"") | N11: =IFERROR(VLOOKUP($A$11&$D$5&$B11&$M$4,TKB_LOP_CHECK!$B$65:$J$860,9,0),"") | O11: =IFERROR(VLOOKUP($A$11&$C$5&$B11&$O$4,TKB_LOP_CHECK!$B$65:$J$860,9,0),"") -> Toán -TTH1 | P11: =IFERROR(VLOOKUP($A$11&$D$5&$B11&$O$4,TKB_LOP_CHECK!$B$65:$J$860,9,0),"") -> HĐ tự chọn -TTH1 | Q11: =IFERROR(VLOOKUP($A$11&$C$5&$B11&$Q$4,TKB_LOP_CHECK!$B$65:$J$860,9,0),"") -> GDTC -3C1 | R11: =IFERROR(VLOOKUP($A$11&$D$5&$B11&$Q$4,TKB_LOP_CHECK!$B$65:$J$860,9,0),"") | S11: =IFERROR(VLOOKUP($A$11&$C$5&$B11&$S$4,TKB_LOP_CHECK!$B$65:$J$860,9,0),"") | T11: =IFERROR(VLOOKUP($A$11&$D$5&$B11&$S$4,TKB_LOP_CHECK!$B$65:$J$860,9,0),"") -> GVVN -4C1 | U11: =IFERROR(VLOOKUP($A$11&$C$5&$B11&$U$4,TKB_LOP_CHECK!$B$65:$J$860,9,0),"") | V11: =IFERROR(VLOOKUP($A$11&$D$5&$B11&$U$4,TKB_LOP_CHECK!$B$65:$J$860,9,0),"") | W11: =IFERROR(VLOOKUP($A$11&$C$5&$B11&$W$4,TKB_LOP_CHECK!$B$65:$J$860,9,0),"") | X11: =IFERROR(VLOOKUP($A$11&$D$5&$B11&$W$4,TKB_LOP_CHECK!$B$65:$J$860,9,0),"") | Y11: =IFERROR(VLOOKUP($A$11&$C$5&$B11&$Y$4,TKB_LOP_CHECK!$B$65:$J$860,9,0),"") | Z11: =IFERROR(VLOOKUP($A$11&$D$5&$B11&$Y$4,TKB_LOP_CHECK!$B$65:$J$860,9,0),"") -> TViệt -5C1 | AA11: =IFERROR(VLOOKUP($A$11&$C$5&$B11&$AA$4,TKB_LOP_CHECK!$B$65:$J$860,9,0),"") | AB11: =IFERROR(VLOOKUP($A$11&$D$5&$B11&$AA$4,TKB_LOP_CHECK!$B$65:$J$860,9,0),"") | AC11: =IFERROR(VLOOKUP($A$11&$C$5&$B11&$AC$4,TKB_LOP_CHECK!$B$65:$J$860,9,0),"") | AD11: =IFERROR(VLOOKUP($A$11&$D$5&$B11&$AC$4,TKB_LOP_CHECK!$B$65:$J$860,9,0),"") | AE11: =IFERROR(VLOOKUP($A$11&$C$5&$B11&$AE$4,TKB_LOP_CHECK!$B$65:$J$860,9,0),"") -> GVNN -5C1 | AF11: =IFERROR(VLOOKUP($A$11&$D$5&$B11&$AE$4,TKB_LOP_CHECK!$B$65:$J$860,9,0),"") | AG11: =IFERROR(VLOOKUP($A$11&$C$5&$B11&$AG$4,TKB_LOP_CHECK!$B$65:$J$860,9,0),"") | AH11: =IFERROR(VLOOKUP($A$11&$D$5&$B11&$AG$4,TKB_LOP_CHECK!$B$65:$J$860,9,0),"") | AI11: =IFERROR(VLOOKUP($A$11&$C$5&$B11&$AI$4,TKB_LOP_CHECK!$B$65:$J$860,9,0),"") -> KHTN -6A1 | AJ11: =IFERROR(VLOOKUP($A$11&$D$5&$B11&$AI$4,TKB_LOP_CHECK!$B$65:$J$860,9,0),"") -> KHTN -8A1 | AK11: =IFERROR(VLOOKUP($A$11&$C$5&$B11&$AK$4,TKB_LOP_CHECK!$B$65:$J$860,9,0),"") | AL11: =IFERROR(VLOOKUP($A$11&$D$5&$B11&$AK$4,TKB_LOP_CHECK!$B$65:$J$860,9,0),"") | AM11: =IFERROR(VLOOKUP($A$11&$C$5&$B11&$AM$4,TKB_LOP_CHECK!$B$65:$J$860,9,0),"") | AN11: =IFERROR(VLOOKUP($A$11&$D$5&$B11&$AM$4,TKB_LOP_CHECK!$B$65:$J$860,9,0),"") | AO11: =IFERROR(VLOOKUP($A$11&$C$5&$B11&$AO$4,TKB_LOP_CHECK!$B$65:$J$860,9,0),"") | AP11: =IFERROR(VLOOKUP($A$11&$D$5&$B11&$AO$4,TKB_LOP_CHECK!$B$65:$J$860,9,0),"") -> TNXH -2C1 | AQ11: =IFERROR(VLOOKUP($A$11&$C$5&$B11&$AQ$4,TKB_LOP_CHECK!$B$65:$J$860,9,0),"") -> GVNN -7A1 | AR11: =IFERROR(VLOOKUP($A$11&$D$5&$B11&$AQ$4,TKB_LOP_CHECK!$B$65:$J$860,9,0),"") -> GVNN -7A1 | AS11: =IFERROR(VLOOKUP($A$11&$C$5&$B11&$AS$4,TKB_LOP_CHECK!$B$65:$J$860,9,0),"") -> Toán -2C1 | AT11: =IFERROR(VLOOKUP($A$11&$D$5&$B11&$AS$4,TKB_LOP_CHECK!$B$65:$J$860,9,0),"") -> Toán -3C1 | AU11: =IFERROR(VLOOKUP($A$11&$C$5&$B11&$AU$4,TKB_LOP_CHECK!$B$65:$J$860,9,0),"") | AV11: =IFERROR(VLOOKUP($A$11&$D$5&$B11&$AU$4,TKB_LOP_CHECK!$B$65:$J$860,9,0),"") | AW11: =IFERROR(VLOOKUP($A$11&$C$5&$B11&$AW$4,TKB_LOP_CHECK!$B$65:$J$860,9,0),"") | AX11: =IFERROR(VLOOKUP($A$11&$D$5&$B11&$AW$4,TKB_LOP_CHECK!$B$65:$J$860,9,0),"") | AY11: =IFERROR(VLOOKUP($A$11&$C$5&$B11&$AY$4,TKB_LOP_CHECK!$B$65:$J$860,9,0),"") | AZ11: =IFERROR(VLOOKUP($A$11&$D$5&$B11&$AY$4,TKB_LOP_CHECK!$B$65:$J$860,9,0),"") | BA11: =IFERROR(VLOOKUP($A$11&$C$5&$B11&$BA$4,TKB_LOP_CHECK!$B$65:$J$860,9,0),"") | BB11: =IFERROR(VLOOKUP($A$11&$D$5&$B11&$BA$4,TKB_LOP_CHECK!$B$65:$J$860,9,0),"") | BC11: =IFERROR(VLOOKUP($A$11&$C$5&$B11&$BC$4,TKB_LOP_CHECK!$B$65:$J$860,9,0),"") | BD11: =IFERROR(VLOOKUP($A$11&$D$5&$B11&$BC$4,TKB_LOP_CHECK!$B$65:$J$860,9,0),"") | BE11: =IFERROR(VLOOKUP($A$11&$C$5&$B11&$BE$4,TKB_LOP_CHECK!$B$65:$J$860,9,0),"") | BF11: =IFERROR(VLOOKUP($A$11&$D$5&$B11&$BE$4,TKB_LOP_CHECK!$B$65:$J$860,9,0),"") | BG11: =IFERROR(VLOOKUP($A$11&$C$5&$B11&$BG$4,TKB_LOP_CHECK!$B$65:$J$860,9,0),"") | BH11: =IFERROR(VLOOKUP($A$11&$D$5&$B11&$BG$4,TKB_LOP_CHECK!$B$65:$J$860,9,0),"") | BI11: =IFERROR(VLOOKUP($A$11&$C$5&$B11&$BI$4,TKB_LOP_CHECK!$B$65:$J$860,9,0),"") | BJ11: =IFERROR(VLOOKUP($A$11&$D$5&$B11&$BI$4,TKB_LOP_CHECK!$B$65:$J$860,9,0),"") | BK11: =IFERROR(VLOOKUP($A$11&$C$5&$B11&$BK$4,TKB_LOP_CHECK!$B$65:$J$860,9,0),"") | BL11: =IFERROR(VLOOKUP($A$11&$D$5&$B11&$BK$4,TKB_LOP_CHECK!$B$65:$J$860,9,0),"") | BM11: =IFERROR(VLOOKUP($A$11&$C$5&$B11&$BM$4,TKB_LOP_CHECK!$B$65:$J$860,9,0),"") | BN11: =IFERROR(VLOOKUP($A$11&$D$5&$B11&$BM$4,TKB_LOP_CHECK!$B$65:$J$860,9,0),"") | BO11: =IFERROR(VLOOKUP($A$11&$C$5&$B11&$BO$4,TKB_LOP_CHECK!$A$65:$J$860,10,0),"") | BP11: =IFERROR(VLOOKUP($A$11&$D$5&$B11&$BO$4,TKB_LOP_CHECK!$A$65:$J$860,10,0),"") | BQ11: =IFERROR(VLOOKUP($A$11&$C$5&$B11&$BQ$4,TKB_LOP_CHECK!$A$65:$J$860,10,0),"") -> GVNN -5C1 | BR11: =IFERROR(VLOOKUP($A$11&$D$5&$B11&$BQ$4,TKB_LOP_CHECK!$A$65:$J$860,10,0),"") -> GVNN -7A1 | BS11: =IFERROR(VLOOKUP($A$11&$C$5&$B11&$BS$4,TKB_LOP_CHECK!$A$65:$J$860,10,0),"") | BT11: =IFERROR(VLOOKUP($A$11&$D$5&$B11&$BS$4,TKB_LOP_CHECK!$A$65:$J$860,10,0),"") | BU11: =IFERROR(VLOOKUP($A$11&$C$5&$B11&$BU$4,TKB_LOP_CHECK!$A$65:$J$860,10,0),"") | BV11: =IFERROR(VLOOKUP($A$11&$D$5&$B11&$BU$4,TKB_LOP_CHECK!$A$65:$J$860,10,0),"")
B12: 2 | C12: =IFERROR(VLOOKUP($A$11&$C$5&$B12&$C$4,TKB_LOP_CHECK!$B$65:$J$860,9,0),"") | D12: =IFERROR(VLOOKUP($A$11&$D$5&$B12&$C$4,TKB_LOP_CHECK!$B$65:$J$860,9,0),"") | E12: =IFERROR(VLOOKUP($A$11&$C$5&$B12&$E$4,TKB_LOP_CHECK!$B$65:$J$860,9,0),"") | F12: =IFERROR(VLOOKUP($A$11&$D$5&$B12&$E$4,TKB_LOP_CHECK!$B$65:$J$860,9,0),"") | G12: =IFERROR(VLOOKUP($A$11&$C$5&$B12&$G$4,TKB_LOP_CHECK!$B$65:$J$860,9,0),"") -> GVNN -4C1 | H12: =IFERROR(VLOOKUP($A$11&$D$5&$B12&$G$4,TKB_LOP_CHECK!$B$65:$J$860,9,0),"") | I12: =IFERROR(VLOOKUP($A$11&$C$5&$B12&$I$4,TKB_LOP_CHECK!$B$65:$J$860,9,0),"") | J12: =IFERROR(VLOOKUP($A$11&$D$5&$B12&$I$4,TKB_LOP_CHECK!$B$65:$J$860,9,0),"") | K12: =IFERROR(VLOOKUP($A$11&$C$5&$B12&$K$4,TKB_LOP_CHECK!$B$65:$J$860,9,0),"") | L12: =IFERROR(VLOOKUP($A$11&$D$5&$B12&$K$4,TKB_LOP_CHECK!$B$65:$J$860,9,0),"") | M12: =IFERROR(VLOOKUP($A$11&$C$5&$B12&$M$4,TKB_LOP_CHECK!$B$65:$J$860,9,0),"") | N12: =IFERROR(VLOOKUP($A$11&$D$5&$B12&$M$4,TKB_LOP_CHECK!$B$65:$J$860,9,0),"") -> GVVN -2A1 | O12: =IFERROR(VLOOKUP($A$11&$C$5&$B12&$O$4,TKB_LOP_CHECK!$B$65:$J$860,9,0),"") -> Toán -TTH1 | P12: =IFERROR(VLOOKUP($A$11&$D$5&$B12&$O$4,TKB_LOP_CHECK!$B$65:$J$860,9,0),"") -> Tìm hiểu thiên nhiên -TTH1 | Q12: =IFERROR(VLOOKUP($A$11&$C$5&$B12&$Q$4,TKB_LOP_CHECK!$B$65:$J$860,9,0),"") -> GDTC -3C1 | R12: =IFERROR(VLOOKUP($A$11&$D$5&$B12&$Q$4,TKB_LOP_CHECK!$B$65:$J$860,9,0),"") | S12: =IFERROR(VLOOKUP($A$11&$C$5&$B12&$S$4,TKB_LOP_CHECK!$B$65:$J$860,9,0),"") -> GVNN -4C1 | T12: =IFERROR(VLOOKUP($A$11&$D$5&$B12&$S$4,TKB_LOP_CHECK!$B$65:$J$860,9,0),"") | U12: =IFERROR(VLOOKUP($A$11&$C$5&$B12&$U$4,TKB_LOP_CHECK!$B$65:$J$860,9,0),"") | V12: =IFERROR(VLOOKUP($A$11&$D$5&$B12&$U$4,TKB_LOP_CHECK!$B$65:$J$860,9,0),"") | W12: =IFERROR(VLOOKUP($A$11&$C$5&$B12&$W$4,TKB_LOP_CHECK!$B$65:$J$860,9,0),"") | X12: =IFERROR(VLOOKUP($A$11&$D$5&$B12&$W$4,TKB_LOP_CHECK!$B$65:$J$860,9,0),"") | Y12: =IFERROR(VLOOKUP($A$11&$C$5&$B12&$Y$4,TKB_LOP_CHECK!$B$65:$J$860,9,0),"") | Z12: =IFERROR(VLOOKUP($A$11&$D$5&$B12&$Y$4,TKB_LOP_CHECK!$B$65:$J$860,9,0),"") -> Toán -3A1 | AA12: =IFERROR(VLOOKUP($A$11&$C$5&$B12&$AA$4,TKB_LOP_CHECK!$B$65:$J$860,9,0),"") | AB12: =IFERROR(VLOOKUP($A$11&$D$5&$B12&$AA$4,TKB_LOP_CHECK!$B$65:$J$860,9,0),"") -> GVVN -2A1 | AC12: =IFERROR(VLOOKUP($A$11&$C$5&$B12&$AC$4,TKB_LOP_CHECK!$B$65:$J$860,9,0),"") | AD12: =IFERROR(VLOOKUP($A$11&$D$5&$B12&$AC$4,TKB_LOP_CHECK!$B$65:$J$860,9,0),"") | AE12: =IFERROR(VLOOKUP($A$11&$C$5&$B12&$AE$4,TKB_LOP_CHECK!$B$65:$J$860,9,0),"") | AF12: =IFERROR(VLOOKUP($A$11&$D$5&$B12&$AE$4,TKB_LOP_CHECK!$B$65:$J$860,9,0),"") -> GVVN -5C1 | AG12: =IFERROR(VLOOKUP($A$11&$C$5&$B12&$AG$4,TKB_LOP_CHECK!$B$65:$J$860,9,0),"") | AH12: =IFERROR(VLOOKUP($A$11&$D$5&$B12&$AG$4,TKB_LOP_CHECK!$B$65:$J$860,9,0),"") -> GVVN -2A1 | AI12: =IFERROR(VLOOKUP($A$11&$C$5&$B12&$AI$4,TKB_LOP_CHECK!$B$65:$J$860,9,0),"") -> KHTN -6A1 | AJ12: =IFERROR(VLOOKUP($A$11&$D$5&$B12&$AI$4,TKB_LOP_CHECK!$B$65:$J$860,9,0),"") -> KHTN -8A1 | AK12: =IFERROR(VLOOKUP($A$11&$C$5&$B12&$AK$4,TKB_LOP_CHECK!$B$65:$J$860,9,0),"") | AL12: =IFERROR(VLOOKUP($A$11&$D$5&$B12&$AK$4,TKB_LOP_CHECK!$B$65:$J$860,9,0),"") | AM12: =IFERROR(VLOOKUP($A$11&$C$5&$B12&$AM$4,TKB_LOP_CHECK!$B$65:$J$860,9,0),"") -> LS&ĐL -5C1 | AN12: =IFERROR(VLOOKUP($A$11&$D$5&$B12&$AM$4,TKB_LOP_CHECK!$B$65:$J$860,9,0),"") -> TViệt -3C1 | AO12: =IFERROR(VLOOKUP($A$11&$C$5&$B12&$AO$4,TKB_LOP_CHECK!$B$65:$J$860,9,0),"") -> TViệt -2C1 | AP12: =IFERROR(VLOOKUP($A$11&$D$5&$B12&$AO$4,TKB_LOP_CHECK!$B$65:$J$860,9,0),"") | AQ12: =IFERROR(VLOOKUP($A$11&$C$5&$B12&$AQ$4,TKB_LOP_CHECK!$B$65:$J$860,9,0),"") | AR12: =IFERROR(VLOOKUP($A$11&$D$5&$B12&$AQ$4,TKB_LOP_CHECK!$B$65:$J$860,9,0),"") | AS12: =IFERROR(VLOOKUP($A$11&$C$5&$B12&$AS$4,TKB_LOP_CHECK!$B$65:$J$860,9,0),"") | AT12: =IFERROR(VLOOKUP($A$11&$D$5&$B12&$AS$4,TKB_LOP_CHECK!$B$65:$J$860,9,0),"") | AU12: =IFERROR(VLOOKUP($A$11&$C$5&$B12&$AU$4,TKB_LOP_CHECK!$B$65:$J$860,9,0),"") | AV12: =IFERROR(VLOOKUP($A$11&$D$5&$B12&$AU$4,TKB_LOP_CHECK!$B$65:$J$860,9,0),"") | AW12: =IFERROR(VLOOKUP($A$11&$C$5&$B12&$AW$4,TKB_LOP_CHECK!$B$65:$J$860,9,0),"") | AX12: =IFERROR(VLOOKUP($A$11&$D$5&$B12&$AW$4,TKB_LOP_CHECK!$B$65:$J$860,9,0),"") | AY12: =IFERROR(VLOOKUP($A$11&$C$5&$B12&$AY$4,TKB_LOP_CHECK!$B$65:$J$860,9,0),"") | AZ12: =IFERROR(VLOOKUP($A$11&$D$5&$B12&$AY$4,TKB_LOP_CHECK!$B$65:$J$860,9,0),"") | BA12: =IFERROR(VLOOKUP($A$11&$C$5&$B12&$BA$4,TKB_LOP_CHECK!$B$65:$J$860,9,0),"") | BB12: =IFERROR(VLOOKUP($A$11&$D$5&$B12&$BA$4,TKB_LOP_CHECK!$B$65:$J$860,9,0),"") | BC12: =IFERROR(VLOOKUP($A$11&$C$5&$B12&$BC$4,TKB_LOP_CHECK!$B$65:$J$860,9,0),"") | BD12: =IFERROR(VLOOKUP($A$11&$D$5&$B12&$BC$4,TKB_LOP_CHECK!$B$65:$J$860,9,0),"") | BE12: =IFERROR(VLOOKUP($A$11&$C$5&$B12&$BE$4,TKB_LOP_CHECK!$B$65:$J$860,9,0),"") | BF12: =IFERROR(VLOOKUP($A$11&$D$5&$B12&$BE$4,TKB_LOP_CHECK!$B$65:$J$860,9,0),"") | BG12: =IFERROR(VLOOKUP($A$11&$C$5&$B12&$BG$4,TKB_LOP_CHECK!$B$65:$J$860,9,0),"") | BH12: =IFERROR(VLOOKUP($A$11&$D$5&$B12&$BG$4,TKB_LOP_CHECK!$B$65:$J$860,9,0),"") | BI12: =IFERROR(VLOOKUP($A$11&$C$5&$B12&$BI$4,TKB_LOP_CHECK!$B$65:$J$860,9,0),"") | BJ12: =IFERROR(VLOOKUP($A$11&$D$5&$B12&$BI$4,TKB_LOP_CHECK!$B$65:$J$860,9,0),"") | BK12: =IFERROR(VLOOKUP($A$11&$C$5&$B12&$BK$4,TKB_LOP_CHECK!$B$65:$J$860,9,0),"") | BL12: =IFERROR(VLOOKUP($A$11&$D$5&$B12&$BK$4,TKB_LOP_CHECK!$B$65:$J$860,9,0),"") | BM12: =IFERROR(VLOOKUP($A$11&$C$5&$B12&$BM$4,TKB_LOP_CHECK!$B$65:$J$860,9,0),"") | BN12: =IFERROR(VLOOKUP($A$11&$D$5&$B12&$BM$4,TKB_LOP_CHECK!$B$65:$J$860,9,0),"") | BO12: =IFERROR(VLOOKUP($A$11&$C$5&$B12&$BO$4,TKB_LOP_CHECK!$A$65:$J$860,10,0),"") | BP12: =IFERROR(VLOOKUP($A$11&$D$5&$B12&$BO$4,TKB_LOP_CHECK!$A$65:$J$860,10,0),"") | BQ12: =IFERROR(VLOOKUP($A$11&$C$5&$B12&$BQ$4,TKB_LOP_CHECK!$A$65:$J$860,10,0),"") -> GVNN -1C1 | BR12: =IFERROR(VLOOKUP($A$11&$D$5&$B12&$BQ$4,TKB_LOP_CHECK!$A$65:$J$860,10,0),"") | BS12: =IFERROR(VLOOKUP($A$11&$C$5&$B12&$BS$4,TKB_LOP_CHECK!$A$65:$J$860,10,0),"") | BT12: =IFERROR(VLOOKUP($A$11&$D$5&$B12&$BS$4,TKB_LOP_CHECK!$A$65:$J$860,10,0),"") | BU12: =IFERROR(VLOOKUP($A$11&$C$5&$B12&$BU$4,TKB_LOP_CHECK!$A$65:$J$860,10,0),"") | BV12: =IFERROR(VLOOKUP($A$11&$D$5&$B12&$BU$4,TKB_LOP_CHECK!$A$65:$J$860,10,0),"")
